Workbook

Sheet MKPR-JPVE DN MON-SUN
A1: MKPR-JPVE SECTION MONDAY- SUNDAY TIME TABLE
A2: TRAIN NO. | B2: 799 | C2: 799 | D2: 799 | E2: 799 | F2: 799 | G2: 799 | H2: 799 | I2: 799 | J2: 799 | K2: 799 | L2: 799 | M2: 799 | N2: 799
B3: MKPR DN
A4: JPVE | B4: NON REVENUE PILOTING FROM MKPR DN TO JPVE DN@25KMPH | C4: 0.31597222 | D4: =C13+'L-7 KEY NEW(JPVE)'!$T$20 -> 0.34392361 | E4: =D13+'L-7 KEY NEW(JPVE)'!$T$20 -> 0.36631944 | F4: =E13+'L-7 KEY NEW(JPVE)'!$T$20 -> 0.38871528 | G4: =F13+'L-7 KEY NEW(JPVE)'!$T$20 -> 0.41111111 | H4: =G13+'L-7 KEY NEW(JPVE)'!$T$20 -> 0.43350694 | I4: =H13+'L-7 KEY NEW(JPVE)'!$T$20 -> 0.45590278 | J4: =I13+'L-7 KEY NEW(JPVE)'!$T$20 -> 0.47829861 | K4: =J13+'L-7 KEY NEW(JPVE)'!$T$20 -> 0.50069444 | ... N4: =M13+'L-7 KEY NEW(JPVE)'!$T$20 -> 0.56788194
A5: JRMR | C5: =C4+'L-7 KEY NEW(JPVE)'!$I5 -> 0.31893519 | D5: =D4+'L-7 KEY NEW(JPVE)'!$D5 -> 0.34628472 | E5: =E4+'L-7 KEY NEW(JPVE)'!$D5 -> 0.36868056 | F5: =F4+'L-7 KEY NEW(JPVE)'!$D5 -> 0.39107639 | G5: =G4+'L-7 KEY NEW(JPVE)'!$D5 -> 0.41347222 | H5: =H4+'L-7 KEY NEW(JPVE)'!$D5 -> 0.43586806 | I5: =I4+'L-7 KEY NEW(JPVE)'!$D5 -> 0.45826389 | J5: =J4+'L-7 KEY NEW(JPVE)'!$D5 -> 0.48065972 | K5: =K4+'L-7 KEY NEW(JPVE)'!$D5 -> 0.50305556 | ... N5: =N4+'L-7 KEY NEW(JPVE)'!$D5 -> 0.57024306
A6: BURI | C6: =C5+'L-7 KEY NEW(JPVE)'!$I6 -> 0.32277778 | D6: =D5+'L-7 KEY NEW(JPVE)'!$D6 -> 0.34931713 | E6: =E5+'L-7 KEY NEW(JPVE)'!$D6 -> 0.37171296 | F6: =F5+'L-7 KEY NEW(JPVE)'!$D6 -> 0.3941088 | G6: =G5+'L-7 KEY NEW(JPVE)'!$D6 -> 0.41650463 | H6: =H5+'L-7 KEY NEW(JPVE)'!$D6 -> 0.43890046 | I6: =I5+'L-7 KEY NEW(JPVE)'!$D6 -> 0.4612963 | J6: =J5+'L-7 KEY NEW(JPVE)'!$D6 -> 0.48369213 | K6: =K5+'L-7 KEY NEW(JPVE)'!$D6 -> 0.50608796 | ... N6: =N5+'L-7 KEY NEW(JPVE)'!$D6 -> 0.57327546
A7: MKPR | C7: =C6+'L-7 KEY NEW(JPVE)'!$I7 -> 0.32928241 | D7: =D6+'L-7 KEY NEW(JPVE)'!$D7 -> 0.3546875 | E7: =E6+'L-7 KEY NEW(JPVE)'!$D7 -> 0.37708333 | F7: =F6+'L-7 KEY NEW(JPVE)'!$D7 -> 0.39947917 | G7: =G6+'L-7 KEY NEW(JPVE)'!$D7 -> 0.421875 | H7: =H6+'L-7 KEY NEW(JPVE)'!$D7 -> 0.44427083 | I7: =I6+'L-7 KEY NEW(JPVE)'!$D7 -> 0.46666667 | J7: =J6+'L-7 KEY NEW(JPVE)'!$D7 -> 0.4890625 | K7: =K6+'L-7 KEY NEW(JPVE)'!$D7 -> 0.51145833 | ... N7: =N6+'L-7 KEY NEW(JPVE)'!$D7 -> 0.57864583
A8: REVERSAL FROM | B8: MKPR DN | C8: MKPR DN | D8: MKPR DN | E8: MKPR DN | F8: MKPR DN | G8: MKPR DN | H8: MKPR DN | I8: MKPR DN | J8: MKPR DN | K8: MKPR DN | L8: MKPR DN | M8: MKPR DN | N8: MKPR DN
A9: TRAIN NO | B9: =B2 -> 799 | C9: =C2 -> 799 | D9: =D2 -> 799 | E9: =E2 -> 799 | F9: =F2 -> 799 | G9: =G2 -> 799 | H9: =H2 -> 799 | I9: =I2 -> 799 | ... N9: =N2 -> 799
A10: MKPR | B10: 0.27777778 | C10: 0.33333333 | D10: =D7+'L-7 KEY NEW(JPVE)'!$T$20 -> 0.35572917 | E10: =E7+'L-7 KEY NEW(JPVE)'!$T$20 -> 0.378125 | F10: =F7+'L-7 KEY NEW(JPVE)'!$T$20 -> 0.40052083 | G10: =G7+'L-7 KEY NEW(JPVE)'!$T$20 -> 0.42291667 | H10: =H7+'L-7 KEY NEW(JPVE)'!$T$20 -> 0.4453125 | I10: =I7+'L-7 KEY NEW(JPVE)'!$T$20 -> 0.46770833 | J10: =J7+'L-7 KEY NEW(JPVE)'!$T$20 -> 0.49010417 | K10: =K7+'L-7 KEY NEW(JPVE)'!$T$20 -> 0.5125 | ... N10: =N7+'L-7 KEY NEW(JPVE)'!$T$20 -> 0.5796875
A11: BURI | B11: =B10+'L-7 KEY NEW(JPVE)'!$R5 -> 0.2837037 | C11: =C10+'L-7 KEY NEW(JPVE)'!$M5 -> 0.33795139 | D11: =D10+'L-7 KEY NEW(JPVE)'!$M5 -> 0.36034722 | E11: =E10+'L-7 KEY NEW(JPVE)'!$M5 -> 0.38274306 | F11: =F10+'L-7 KEY NEW(JPVE)'!$M5 -> 0.40513889 | G11: =G10+'L-7 KEY NEW(JPVE)'!$M5 -> 0.42753472 | H11: =H10+'L-7 KEY NEW(JPVE)'!$M5 -> 0.44993056 | I11: =I10+'L-7 KEY NEW(JPVE)'!$M5 -> 0.47232639 | J11: =J10+'L-7 KEY NEW(JPVE)'!$M5 -> 0.49472222 | ... N11: =N10+'L-7 KEY NEW(JPVE)'!$M5 -> 0.58430556
A12: JRMR | B12: =B11+'L-7 KEY NEW(JPVE)'!$R6 -> 0.2875463 | C12: =C11+'L-7 KEY NEW(JPVE)'!$M6 -> 0.3409838 | D12: =D11+'L-7 KEY NEW(JPVE)'!$M6 -> 0.36337963 | E12: =E11+'L-7 KEY NEW(JPVE)'!$M6 -> 0.38577546 | F12: =F11+'L-7 KEY NEW(JPVE)'!$M6 -> 0.4081713 | G12: =G11+'L-7 KEY NEW(JPVE)'!$M6 -> 0.43056713 | H12: =H11+'L-7 KEY NEW(JPVE)'!$M6 -> 0.45296296 | I12: =I11+'L-7 KEY NEW(JPVE)'!$M6 -> 0.4753588 | J12: =J11+'L-7 KEY NEW(JPVE)'!$M6 -> 0.49775463 | ... N12: =N11+'L-7 KEY NEW(JPVE)'!$M6 -> 0.58733796
A13: JPVE | B13: =B12+'L-7 KEY NEW(JPVE)'!$R7 -> 0.2900463 | C13: =C12+'L-7 KEY NEW(JPVE)'!$M7 -> 0.34288194 | D13: =D12+'L-7 KEY NEW(JPVE)'!$M7 -> 0.36527778 | E13: =E12+'L-7 KEY NEW(JPVE)'!$M7 -> 0.38767361 | F13: =F12+'L-7 KEY NEW(JPVE)'!$M7 -> 0.41006944 | G13: =G12+'L-7 KEY NEW(JPVE)'!$M7 -> 0.43246528 | H13: =H12+'L-7 KEY NEW(JPVE)'!$M7 -> 0.45486111 | I13: =I12+'L-7 KEY NEW(JPVE)'!$M7 -> 0.47725694 | J13: =J12+'L-7 KEY NEW(JPVE)'!$M7 -> 0.49965278 | ... N13: =N12+'L-7 KEY NEW(JPVE)'!$M7 -> 0.58923611
A14: REVERSAL FROM | B14: JPVE DN | C14: JPVE DN | D14: JPVE DN | E14: JPVE DN | F14: JPVE DN | G14: JPVE DN | H14: JPVE DN | I14: JPVE DN | J14: JPVE DN | K14: JPVE DN | L14: JPVE DN | M14: JPVE DN | N14: JPVE DN
A16: TRAIN NO. | B16: 799 | C16: 799 | D16: 799 | E16: 799 | F16: 799 | G16: 799 | H16: 799 | I16: 799 | J16: 799 | K16: 799 | L16: 799 | M16: 799 | N16: 799
A17: JPVE | B17: =N13+'L-7 KEY NEW(JPVE)'!$T$20 -> 0.59027778 | C17: =B26+'L-7 KEY NEW(JPVE)'!$T$20 -> 0.61267361 | D17: =C26+'L-7 KEY NEW(JPVE)'!$T$20 -> 0.63506944 | E17: =D26+'L-7 KEY NEW(JPVE)'!$T$20 -> 0.65746528 | F17: =E26+'L-7 KEY NEW(JPVE)'!$T$20 -> 0.67986111 | G17: =F26+'L-7 KEY NEW(JPVE)'!$T$20 -> 0.70225694 | H17: =G26+'L-7 KEY NEW(JPVE)'!$T$20 -> 0.72465278 | I17: =H26+'L-7 KEY NEW(JPVE)'!$T$20 -> 0.74704861 | J17: =I26+'L-7 KEY NEW(JPVE)'!$T$20 -> 0.76944444 | K17: 0.80277778 | L17: =K26+'L-7 KEY NEW(JPVE)'!$T$20 -> 0.8265625 | M17: =L26+'L-7 KEY NEW(JPVE)'!$T$20 -> 0.84895833 | N17: =M26+'L-7 KEY NEW(JPVE)'!$T$20 -> 0.87135417
A18: JRMR | B18: =B17+'L-7 KEY NEW(JPVE)'!$D5 -> 0.59263889 | C18: =C17+'L-7 KEY NEW(JPVE)'!$D5 -> 0.61503472 | D18: =D17+'L-7 KEY NEW(JPVE)'!$D5 -> 0.63743056 | E18: =E17+'L-7 KEY NEW(JPVE)'!$D5 -> 0.65982639 | F18: =F17+'L-7 KEY NEW(JPVE)'!$D5 -> 0.68222222 | G18: =G17+'L-7 KEY NEW(JPVE)'!$D5 -> 0.70461806 | H18: =H17+'L-7 KEY NEW(JPVE)'!$D5 -> 0.72701389 | I18: =I17+'L-7 KEY NEW(JPVE)'!$D5 -> 0.74940972 | ... N18: =N17+'L-7 KEY NEW(JPVE)'!$D5 -> 0.87371528
A19: BURI | B19: =B18+'L-7 KEY NEW(JPVE)'!$D6 -> 0.5956713 | C19: =C18+'L-7 KEY NEW(JPVE)'!$D6 -> 0.61806713 | D19: =D18+'L-7 KEY NEW(JPVE)'!$D6 -> 0.64046296 | E19: =E18+'L-7 KEY NEW(JPVE)'!$D6 -> 0.6628588 | F19: =F18+'L-7 KEY NEW(JPVE)'!$D6 -> 0.68525463 | G19: =G18+'L-7 KEY NEW(JPVE)'!$D6 -> 0.70765046 | H19: =H18+'L-7 KEY NEW(JPVE)'!$D6 -> 0.7300463 | I19: =I18+'L-7 KEY NEW(JPVE)'!$D6 -> 0.75244213 | ... N19: =N18+'L-7 KEY NEW(JPVE)'!$D6 -> 0.87674769
A20: MKPR | B20: =B19+'L-7 KEY NEW(JPVE)'!$D7 -> 0.60104167 | C20: =C19+'L-7 KEY NEW(JPVE)'!$D7 -> 0.6234375 | D20: =D19+'L-7 KEY NEW(JPVE)'!$D7 -> 0.64583333 | E20: =E19+'L-7 KEY NEW(JPVE)'!$D7 -> 0.66822917 | F20: =F19+'L-7 KEY NEW(JPVE)'!$D7 -> 0.690625 | G20: =G19+'L-7 KEY NEW(JPVE)'!$D7 -> 0.71302083 | H20: =H19+'L-7 KEY NEW(JPVE)'!$D7 -> 0.73541667 | I20: =I19+'L-7 KEY NEW(JPVE)'!$D7 -> 0.7578125 | ... N20: =N19+'L-7 KEY NEW(JPVE)'!$D7 -> 0.88211806
A21: REVERSAL FROM | B21: MKPR DN | C21: MKPR DN | D21: MKPR DN | E21: MKPR DN | F21: MKPR DN | G21: MKPR DN | H21: MKPR DN | I21: MKPR DN | J21: MKPR DN | K21: MKPR DN | L21: MKPR DN | M21: MKPR DN | N21: MKPR DN
A22: TRAIN NO | B22: =B16 -> 799 | C22: =C16 -> 799 | D22: =D16 -> 799 | E22: =E16 -> 799 | F22: =F16 -> 799 | G22: =G16 -> 799 | H22: =H16 -> 799 | I22: =I16 -> 799 | ... N22: =N16 -> 799
A23: MKPR | B23: =B20+'L-7 KEY NEW(JPVE)'!$T$20 -> 0.60208333 | C23: =C20+'L-7 KEY NEW(JPVE)'!$T$20 -> 0.62447917 | D23: =D20+'L-7 KEY NEW(JPVE)'!$T$20 -> 0.646875 | E23: =E20+'L-7 KEY NEW(JPVE)'!$T$20 -> 0.66927083 | F23: =F20+'L-7 KEY NEW(JPVE)'!$T$20 -> 0.69166667 | G23: =G20+'L-7 KEY NEW(JPVE)'!$T$20 -> 0.7140625 | H23: =H20+'L-7 KEY NEW(JPVE)'!$T$20 -> 0.73645833 | I23: =I20+'L-7 KEY NEW(JPVE)'!$T$20 -> 0.75885417 | J23: =J20+'L-7 KEY NEW(JPVE)'!$T$20 -> 0.78125 | K23: 0.81597222 | L23: =L20+'L-7 KEY NEW(JPVE)'!$T$20 -> 0.83836806 | M23: =M20+'L-7 KEY NEW(JPVE)'!$T$20 -> 0.86076389 | N23: =N20+'L-7 KEY NEW(JPVE)'!$T$20 -> 0.88315972
A24: BURI | B24: =B23+'L-7 KEY NEW(JPVE)'!$M5 -> 0.60670139 | C24: =C23+'L-7 KEY NEW(JPVE)'!$M5 -> 0.62909722 | D24: =D23+'L-7 KEY NEW(JPVE)'!$M5 -> 0.65149306 | E24: =E23+'L-7 KEY NEW(JPVE)'!$M5 -> 0.67388889 | F24: =F23+'L-7 KEY NEW(JPVE)'!$M5 -> 0.69628472 | G24: =G23+'L-7 KEY NEW(JPVE)'!$M5 -> 0.71868056 | H24: =H23+'L-7 KEY NEW(JPVE)'!$M5 -> 0.74107639 | I24: =I23+'L-7 KEY NEW(JPVE)'!$M5 -> 0.76347222 | ... N24: =N23+'L-7 KEY NEW(JPVE)'!$M5 -> 0.88777778
A25: JRMR | B25: =B24+'L-7 KEY NEW(JPVE)'!$M6 -> 0.6097338 | C25: =C24+'L-7 KEY NEW(JPVE)'!$M6 -> 0.63212963 | D25: =D24+'L-7 KEY NEW(JPVE)'!$M6 -> 0.65452546 | E25: =E24+'L-7 KEY NEW(JPVE)'!$M6 -> 0.6769213 | F25: =F24+'L-7 KEY NEW(JPVE)'!$M6 -> 0.69931713 | G25: =G24+'L-7 KEY NEW(JPVE)'!$M6 -> 0.72171296 | H25: =H24+'L-7 KEY NEW(JPVE)'!$M6 -> 0.7441088 | I25: =I24+'L-7 KEY NEW(JPVE)'!$M6 -> 0.76650463 | ... N25: =N24+'L-7 KEY NEW(JPVE)'!$M6 -> 0.89081019
A26: JPVE | B26: =B25+'L-7 KEY NEW(JPVE)'!$M7 -> 0.61163194 | C26: =C25+'L-7 KEY NEW(JPVE)'!$M7 -> 0.63402778 | D26: =D25+'L-7 KEY NEW(JPVE)'!$M7 -> 0.65642361 | E26: =E25+'L-7 KEY NEW(JPVE)'!$M7 -> 0.67881944 | F26: =F25+'L-7 KEY NEW(JPVE)'!$M7 -> 0.70121528 | G26: =G25+'L-7 KEY NEW(JPVE)'!$M7 -> 0.72361111 | H26: =H25+'L-7 KEY NEW(JPVE)'!$M7 -> 0.74600694 | I26: =I25+'L-7 KEY NEW(JPVE)'!$M7 -> 0.76840278 | ... N26: =N25+'L-7 KEY NEW(JPVE)'!$M7 -> 0.89270833
A27: REVERSAL FROM | B27: JPVE DN | C27: JPVE DN | D27: JPVE DN | E27: JPVE DN | F27: JPVE DN | G27: JPVE DN | H27: JPVE DN | I27: JPVE DN | J27: JPVE DN | K27: JPVE DN | L27: JPVE DN | M27: JPVE DN | N27: JPVE DN
A29: TRAIN NO. | B29: 799 | C29: 799 | D29: 799 | J29: TOTAL TRIPS & KMS IN TIME-TABLE
A30: JPVE | B30: =N26+'L-7 KEY NEW(JPVE)'!$T$20 -> 0.89375 | C30: 0.88888889 | D30: 0.91666667 | J30: SECTION | L30: KMS | M30: NO OF TRIPS | N30: TOTAL RUN KMS
A31: JRMR | B31: =B30+'L-7 KEY NEW(JPVE)'!$D5 -> 0.89611111 | C31: =C30+'L-7 KEY NEW(JPVE)'!$D5 -> 0.89125 | D31: =D30+'L-7 KEY NEW(JPVE)'!$D5 -> 0.91902778
A32: BURI | B32: =B31+'L-7 KEY NEW(JPVE)'!$D6 -> 0.89914352 | C32: =C31+'L-7 KEY NEW(JPVE)'!$D6 -> 0.89428241 | D32: =D31+'L-7 KEY NEW(JPVE)'!$D6 -> 0.92206019 | J32: MKPR-JPVE | L32: 4.96 | M32: 27 | N32: =L32*M32 -> 133.92
A33: MKPR | B33: =B32+'L-7 KEY NEW(JPVE)'!$D7 -> 0.90451389 | C33: =C32+'L-7 KEY NEW(JPVE)'!$D7 -> 0.89965278 | D33: =D32+'L-7 KEY NEW(JPVE)'!$D7 -> 0.92743056 | J33: JPVE-MKPR | L33: 4.96 | M33: 28 | N33: =L33*M33 -> 138.88
A34: REVERSAL FROM | B34: MKPR DN | C34: MKPR DN | D34: MKPR DN | J34: TOTAL | M34: =SUM(M32:M33) -> 55 | N34: =SUM(N32:N33) -> 272.8
A35: TRAIN NO | B35: =B29 -> 799 | C35: =C29 -> 799 | D35: =D29 -> 799 | E35: HEADWAY | J35: FIRST AND LAST TRAIN TIMINGS
A36: MKPR | B36: =B33+'L-7 KEY NEW(JPVE)'!$T$20 -> 0.90555556 | C36: 0.90277778 | D36: EMPTY AT MKPR DN PF THEN STABLE AT MKPR DN PF | E36: 33 MIN 00 SEC | J36: FROM | K36: FROM | L36: FIRST TRAIN | N36: LAST TRAIN
A37: BURI | B37: =B36+'L-7 KEY NEW(JPVE)'!$M5 -> 0.91017361 | C37: =C36+'L-7 KEY NEW(JPVE)'!$M5 -> 0.90739583 | J37: JPVE DN | K37: MKPR DN | L37: 0.33333333 | N37: 0.91666667
A38: JRMR | B38: =B37+'L-7 KEY NEW(JPVE)'!$M6 -> 0.91320602 | C38: =C37+'L-7 KEY NEW(JPVE)'!$M6 -> 0.91042824 | E38: REVERSAL TIME AT MKPR DN & JPVE DN PF | H38: DWELL TIME AT JRMR & BURI | J38: MKPR DN | K38: JPVE DN | L38: 0.34392361 | N38: 0.90277778
A39: JPVE | B39: =B38+'L-7 KEY NEW(JPVE)'!$M7 -> 0.91510417 | C39: =C38+'L-7 KEY NEW(JPVE)'!$M7 -> 0.91232639 | J39: MUPR UP | K39: JPVE DN | L39: 0.25 | N39: 0.82916667
A40: REVERSAL FROM | B40: JPVE DN | C40: JPVE DN | D40: MKPR DN STABLE | E40: 1 MIN 30 SECS | H40: 40 SECS | J40: SVVR UP | K40: JPVE DN | L40: 0.25 | N40: 0.82083333

Sheet SEQUENCE JPWD001_XXXX2025(UP)
A1: SEQUENCE AT JPVE/MKPR UP PLATFORMS (WEEKDAY,SATURDAY & SUNDAY) | I1: DATE:-
A2: S NO. | B2: Train No. | C2: Train Set | D2: Depature Time | G2: Section/DOT | H2: Sr. No of authroity to proceed | I2: Private No details w.r.t authority to proceed
D3: From | E3: As per TT | F3: Actual
A4: 1 | B4: 799 | D4: JPVE | E4: 08:00:00 (REVENUE PILOTING) | G4: MKPR-JPVE | I4: occ | J4: JPVE
A5: 2 | B5: 799 | D5: MKPR | E5: 0.34722222 | G5: JPVE-MKPR | I5: occ | J5: MKPR
A6: 3 | B6: 799 | D6: JPVE | E6: 0.35833333 | G6: MKPR-JPVE | I6: occ | J6: JPVE
A7: 4 | B7: 799 | D7: MKPR | E7: =E5+$A$48 -> 0.37083333 | G7: JPVE-MKPR | I7: occ | J7: MKPR
A8: 5 | B8: 799 | D8: JPVE | E8: =E6+$A$48 -> 0.38194444 | G8: MKPR-JPVE | I8: occ | J8: JPVE
A9: 6 | B9: 799 | D9: MKPR | E9: =E7+$A$48 -> 0.39444444 | G9: JPVE-MKPR | I9: occ | J9: MKPR
A10: 7 | B10: 799 | D10: JPVE | E10: =E8+$A$48 -> 0.40555556 | G10: MKPR-JPVE | I10: occ | J10: JPVE
A11: 8 | B11: 799 | D11: MKPR | E11: =E9+$A$48 -> 0.41805556 | G11: JPVE-MKPR | I11: occ | J11: MKPR
A12: 9 | B12: 799 | D12: JPVE | E12: =E10+$A$48 -> 0.42916667 | G12: MKPR-JPVE | I12: occ | J12: JPVE
A13: 10 | B13: 799 | D13: MKPR | E13: =E11+$A$48 -> 0.44166667 | G13: JPVE-MKPR | I13: occ | J13: MKPR
A14: 11 | B14: 799 | D14: JPVE | E14: =E12+$A$48 -> 0.45277778 | G14: MKPR-JPVE | I14: occ | J14: JPVE
A15: 12 | B15: 799 | D15: MKPR | E15: =E13+$A$48 -> 0.46527778 | G15: JPVE-MKPR | I15: occ | J15: MKPR
A16: 13 | B16: 799 | D16: JPVE | E16: =E14+$A$48 -> 0.47638889 | G16: MKPR-JPVE | I16: occ | J16: JPVE
A17: 14 | B17: 799 | D17: MKPR | E17: =E15+$A$48 -> 0.48888889 | G17: JPVE-MKPR | I17: occ | J17: MKPR
A18: 15 | B18: 799 | D18: JPVE | E18: =E16+$A$48 -> 0.5 | G18: MKPR-JPVE | I18: occ | J18: JPVE
... A45: 42 | B45: 799 | D45: MKPR | E45: =E43+$A$48 -> 0.81944444 | G45: JPVE-MKPR | I45: occ | J45: MKPR
A46: 43 | B46: 799 | D46: JPVE | E46: 0.83333333 | G46: MKPR-JPVE | I46: occ | J46: JPVE
A47: 44 | B47: 799 | D47: MKPR | E47: 20:17:45 (NON REVENUE) | G47: JPVE-MKPR | I47: occ | J47: MKPR
A48: 0.023611111

Sheet SEQUENCE JPWD001_XXXX2025(DN)
A1: SEQUENCE AT JPVE/MKPR DN PLATFORMS (WEEKDAY,SATURDAY & SUNDAY) | I1: DATE:-
A2: S NO. | B2: Train No. | C2: Train Set | D2: Depature Time | G2: Section/DOT | H2: Sr. No of authroity to proceed | I2: Private No details w.r.t authority to proceed
D3: From | E3: As per TT | F3: Actual
A4: 1 | B4: 798 | D4: MKPR | E4: 08:00:00 (REVENUE PILOTING) | G4: MKPR-JPVE | I4: occ | J4: MKPR
A5: 2 | B5: 798 | D5: JPVE | E5: 0.34652778 | G5: JPVE-MKPR | I5: occ | J5: JPVE
A6: 3 | B6: 798 | D6: MKPR | E6: 0.35902778 | G6: MKPR-JPVE | I6: occ | J6: MKPR
A7: 4 | B7: 798 | D7: JPVE | E7: 0.37013889 | G7: JPVE-MKPR | I7: occ | J7: JPVE
A8: 5 | B8: 798 | D8: MKPR | E8: 0.38263889 | G8: MKPR-JPVE | I8: occ | J8: MKPR
A9: 6 | B9: 798 | D9: JPVE | E9: 0.39375 | G9: JPVE-MKPR | I9: occ | J9: JPVE
A10: 7 | B10: 798 | D10: MKPR | E10: 0.40625 | G10: MKPR-JPVE | I10: occ | J10: MKPR
A11: 8 | B11: 798 | D11: JPVE | E11: 0.41736111 | G11: JPVE-MKPR | I11: occ | J11: JPVE
A12: 9 | B12: 798 | D12: MKPR | E12: 0.42986111 | G12: MKPR-JPVE | I12: occ | J12: MKPR
A13: 10 | B13: 798 | D13: JPVE | E13: 0.44097222 | G13: JPVE-MKPR | I13: occ | J13: JPVE
A14: 11 | B14: 798 | D14: MKPR | E14: 0.45347222 | G14: MKPR-JPVE | I14: occ | J14: MKPR
A15: 12 | B15: 798 | D15: JPVE | E15: 0.46458333 | G15: JPVE-MKPR | I15: occ | J15: JPVE
A16: 13 | B16: 798 | D16: MKPR | E16: 0.47708333 | G16: MKPR-JPVE | I16: occ | J16: MKPR
... A46: 43 | B46: 798 | D46: MKPR | E46: 0.83333333 | G46: MKPR-JPVE | I46: occ | J46: MKPR
A47: 44 | B47: 798 | D47: JPVE | E47: 20:15:30 (NON REVENUE) | G47: JPVE-MKPR | I47: occ | J47: JPVE
A48: 0.011111111

Sheet TIME TABLE JPWD001_XXXX2025
A1: PATLIPUTRA-BHOOTNATH SECTION ALL DAY TIME TABLE | L1: T.T VERSION | M1: L2_001_XXXX2025
A2: TRAIN NO. | C2: 201 | D2: 201 | E2: 201 | F2: 201 | G2: 201 | H2: 201 | I2: 201 | J2: 201 | K2: 201 | L2: 201
A3: STATION | B3: Piloting from Patliputra DN to Bhoonath DN with speed limit of 10 Kmph | C3: DN DOT | D3: DN DOT | E3: DN DOT | F3: DN DOT | G3: DN DOT | H3: DN DOT | I3: DN DOT | J3: DN DOT | K3: DN DOT | L3: DN DOT | M3: DN DOT | N3: DN DOT
A4: PATLIPUTRA | C4: 0.31597222 | D4: =C12+'L-7 KEY MKPR- JPVE(FINAL)'!$N$10 -> 0.34375 | E4: =D12+'L-7 KEY MKPR- JPVE(FINAL)'!$N$10 -> 0.36458333 | F4: =E12+'L-7 KEY MKPR- JPVE(FINAL)'!$N$10 -> 0.38541667 | G4: =F12+'L-7 KEY MKPR- JPVE(FINAL)'!$N$10 -> 0.40625 | H4: =G12+'L-7 KEY MKPR- JPVE(FINAL)'!$N$10 -> 0.42708333 | I4: =H12+'L-7 KEY MKPR- JPVE(FINAL)'!$N$10 -> 0.44791667 | J4: =I12+'L-7 KEY MKPR- JPVE(FINAL)'!$N$10 -> 0.46875 | K4: =J12+'L-7 KEY MKPR- JPVE(FINAL)'!$N$10 -> 0.48958333 | ... N4: =M12+'L-7 KEY MKPR- JPVE(FINAL)'!$N$10 -> 0.55208333
A5: ZERO MILE | C5: =C4+'L-7 KEY MKPR- JPVE(FINAL)'!$F5 -> 0.32393519 | D5: =D4+'L-7 KEY MKPR- JPVE(FINAL)'!$D5 -> 0.3475463 | E5: =E4+'L-7 KEY MKPR- JPVE(FINAL)'!$D5 -> 0.36837963 | F5: =F4+'L-7 KEY MKPR- JPVE(FINAL)'!$D5 -> 0.38921296 | G5: =G4+'L-7 KEY MKPR- JPVE(FINAL)'!$D5 -> 0.4100463 | H5: =H4+'L-7 KEY MKPR- JPVE(FINAL)'!$D5 -> 0.43087963 | I5: =I4+'L-7 KEY MKPR- JPVE(FINAL)'!$D5 -> 0.45171296 | J5: =J4+'L-7 KEY MKPR- JPVE(FINAL)'!$D5 -> 0.4725463 | K5: =K4+'L-7 KEY MKPR- JPVE(FINAL)'!$D5 -> 0.49337963 | ... N5: =N4+'L-7 KEY MKPR- JPVE(FINAL)'!$D5 -> 0.55587963 | R5: =E6-E5 -> 0.0030555556
A6: BHOOTNATH | C6: =C5+'L-7 KEY MKPR- JPVE(FINAL)'!$F6 -> 0.33081019 | D6: =D5+'L-7 KEY MKPR- JPVE(FINAL)'!$D6 -> 0.35060185 | E6: =E5+'L-7 KEY MKPR- JPVE(FINAL)'!$D6 -> 0.37143519 | F6: =F5+'L-7 KEY MKPR- JPVE(FINAL)'!$D6 -> 0.39226852 | G6: =G5+'L-7 KEY MKPR- JPVE(FINAL)'!$D6 -> 0.41310185 | H6: =H5+'L-7 KEY MKPR- JPVE(FINAL)'!$D6 -> 0.43393519 | I6: =I5+'L-7 KEY MKPR- JPVE(FINAL)'!$D6 -> 0.45476852 | J6: =J5+'L-7 KEY MKPR- JPVE(FINAL)'!$D6 -> 0.47560185 | K6: =K5+'L-7 KEY MKPR- JPVE(FINAL)'!$D6 -> 0.49643519 | ... N6: =N5+'L-7 KEY MKPR- JPVE(FINAL)'!$D6 -> 0.55893519 | R6: =#REF!-E6 -> #REF!
A7: REVERSAL FROM | C7: Bhootnath DN | D7: Bhootnath DN | E7: Bhootnath DN | F7: Bhootnath DN | G7: Bhootnath DN | H7: Bhootnath DN | I7: Bhootnath DN | J7: Bhootnath DN | K7: Bhootnath DN | L7: Bhootnath DN | M7: Bhootnath DN | N7: Bhootnath DN
A8: TRAIN NO. | C8: 201 | D8: 201 | E8: 201 | F8: 201 | G8: 201 | H8: 201 | I8: 201 | J8: 201 | K8: 201 | L8: 201 | M8: 201 | N8: 201
A9: STATION | C9: UP DOT | D9: UP DOT | E9: UP DOT | F9: UP DOT | G9: UP DOT | H9: UP DOT | I9: UP DOT | J9: UP DOT | K9: UP DOT | L9: UP DOT | M9: UP DOT | N9: UP DOT
A10: BHOOTNATH | C10: 0.33333333 | D10: =D6+'L-7 KEY MKPR- JPVE(FINAL)'!$N$10 -> 0.35416667 | E10: =E6+'L-7 KEY MKPR- JPVE(FINAL)'!$N$10 -> 0.375 | F10: =F6+'L-7 KEY MKPR- JPVE(FINAL)'!$N$10 -> 0.39583333 | G10: =G6+'L-7 KEY MKPR- JPVE(FINAL)'!$N$10 -> 0.41666667 | H10: =H6+'L-7 KEY MKPR- JPVE(FINAL)'!$N$10 -> 0.4375 | I10: =I6+'L-7 KEY MKPR- JPVE(FINAL)'!$N$10 -> 0.45833333 | J10: =J6+'L-7 KEY MKPR- JPVE(FINAL)'!$N$10 -> 0.47916667 | K10: =K6+'L-7 KEY MKPR- JPVE(FINAL)'!$N$10 -> 0.5 | ... N10: =N6+'L-7 KEY MKPR- JPVE(FINAL)'!$N$10 -> 0.5625 | R10: =D12-D11 -> 0.0033333333
A11: ZERO MILE | C11: =C10+'L-7 KEY MKPR- JPVE(FINAL)'!$J5 -> 0.33685185 | D11: =D10+'L-7 KEY MKPR- JPVE(FINAL)'!$J5 -> 0.35768519 | E11: =E10+'L-7 KEY MKPR- JPVE(FINAL)'!$J5 -> 0.37851852 | F11: =F10+'L-7 KEY MKPR- JPVE(FINAL)'!$J5 -> 0.39935185 | G11: =G10+'L-7 KEY MKPR- JPVE(FINAL)'!$J5 -> 0.42018519 | H11: =H10+'L-7 KEY MKPR- JPVE(FINAL)'!$J5 -> 0.44101852 | I11: =I10+'L-7 KEY MKPR- JPVE(FINAL)'!$J5 -> 0.46185185 | J11: =J10+'L-7 KEY MKPR- JPVE(FINAL)'!$J5 -> 0.48268519 | ... N11: =N10+'L-7 KEY MKPR- JPVE(FINAL)'!$J5 -> 0.56601852 | R11: =#REF!-D12 -> #REF!
A12: PATLIPUTRA | C12: =C11+'L-7 KEY MKPR- JPVE(FINAL)'!$J6 -> 0.34018519 | D12: =D11+'L-7 KEY MKPR- JPVE(FINAL)'!$J6 -> 0.36101852 | E12: =E11+'L-7 KEY MKPR- JPVE(FINAL)'!$J6 -> 0.38185185 | F12: =F11+'L-7 KEY MKPR- JPVE(FINAL)'!$J6 -> 0.40268519 | G12: =G11+'L-7 KEY MKPR- JPVE(FINAL)'!$J6 -> 0.42351852 | H12: =H11+'L-7 KEY MKPR- JPVE(FINAL)'!$J6 -> 0.44435185 | I12: =I11+'L-7 KEY MKPR- JPVE(FINAL)'!$J6 -> 0.46518519 | J12: =J11+'L-7 KEY MKPR- JPVE(FINAL)'!$J6 -> 0.48601852 | ... N12: =N11+'L-7 KEY MKPR- JPVE(FINAL)'!$J6 -> 0.56935185 | S12: 10
A13: REVERSAL FROM | C13: Patliputra DN | D13: Patliputra DN | E13: Patliputra DN | F13: Patliputra DN | G13: Patliputra DN | H13: Patliputra DN | I13: Patliputra DN | J13: Patliputra DN | K13: Patliputra DN | L13: Patliputra DN | M13: Patliputra DN | N13: Patliputra DN
R14: =#REF!-E6 -> #REF! | S14: 39
A15: TRAIN NO. | B15: 201 | C15: 201 | D15: 201 | E15: 201 | F15: 201 | G15: 201 | H15: 201 | I15: 201 | J15: 201 | K15: 201 | L15: 201 | M15: 201 | N15: 201
A16: STATION | B16: DN DOT | C16: DN DOT | D16: DN DOT | E16: DN DOT | F16: DN DOT | G16: DN DOT | H16: DN DOT | I16: DN DOT | J16: DN DOT | K16: DN DOT | L16: DN DOT | M16: DN DOT | N16: DN DOT
A17: PATLIPUTRA | B17: =N12+'L-7 KEY MKPR- JPVE(FINAL)'!$N$10 -> 0.57291667 | C17: =B25+'L-7 KEY MKPR- JPVE(FINAL)'!$N$10 -> 0.59375 | D17: =C25+'L-7 KEY MKPR- JPVE(FINAL)'!$N$10 -> 0.61458333 | E17: =D25+'L-7 KEY MKPR- JPVE(FINAL)'!$N$10 -> 0.63541667 | F17: =E25+'L-7 KEY MKPR- JPVE(FINAL)'!$N$10 -> 0.65625 | G17: =F25+'L-7 KEY MKPR- JPVE(FINAL)'!$N$10 -> 0.67708333 | H17: =G25+'L-7 KEY MKPR- JPVE(FINAL)'!$N$10 -> 0.69791667 | I17: =H25+'L-7 KEY MKPR- JPVE(FINAL)'!$N$10 -> 0.71875 | J17: =I25+'L-7 KEY MKPR- JPVE(FINAL)'!$N$10 -> 0.73958333 | ... N17: =M25+'L-7 KEY MKPR- JPVE(FINAL)'!$N$10 -> 0.82291667 | R17: =#REF!-E10 -> #REF!
A18: ZERO MILE | B18: =B17+'L-7 KEY MKPR- JPVE(FINAL)'!$D5 -> 0.57671296 | C18: =C17+'L-7 KEY MKPR- JPVE(FINAL)'!$D5 -> 0.5975463 | D18: =D17+'L-7 KEY MKPR- JPVE(FINAL)'!$D5 -> 0.61837963 | E18: =E17+'L-7 KEY MKPR- JPVE(FINAL)'!$D5 -> 0.63921296 | F18: =F17+'L-7 KEY MKPR- JPVE(FINAL)'!$D5 -> 0.6600463 | G18: =G17+'L-7 KEY MKPR- JPVE(FINAL)'!$D5 -> 0.68087963 | H18: =H17+'L-7 KEY MKPR- JPVE(FINAL)'!$D5 -> 0.70171296 | I18: =I17+'L-7 KEY MKPR- JPVE(FINAL)'!$D5 -> 0.7225463 | ... N18: =N17+'L-7 KEY MKPR- JPVE(FINAL)'!$D5 -> 0.82671296
A19: BHOOTNATH | B19: =B18+'L-7 KEY MKPR- JPVE(FINAL)'!$D6 -> 0.57976852 | C19: =C18+'L-7 KEY MKPR- JPVE(FINAL)'!$D6 -> 0.60060185 | D19: =D18+'L-7 KEY MKPR- JPVE(FINAL)'!$D6 -> 0.62143519 | E19: =E18+'L-7 KEY MKPR- JPVE(FINAL)'!$D6 -> 0.64226852 | F19: =F18+'L-7 KEY MKPR- JPVE(FINAL)'!$D6 -> 0.66310185 | G19: =G18+'L-7 KEY MKPR- JPVE(FINAL)'!$D6 -> 0.68393519 | H19: =H18+'L-7 KEY MKPR- JPVE(FINAL)'!$D6 -> 0.70476852 | I19: =I18+'L-7 KEY MKPR- JPVE(FINAL)'!$D6 -> 0.72560185 | ... N19: =N18+'L-7 KEY MKPR- JPVE(FINAL)'!$D6 -> 0.82976852
A20: REVERSAL FROM | B20: Bhootnath DN | C20: Bhootnath DN | D20: Bhootnath DN | E20: Bhootnath DN | F20: Bhootnath DN | G20: Bhootnath DN | H20: Bhootnath DN | I20: Bhootnath DN | J20: Bhootnath DN | K20: Bhootnath DN | L20: Bhootnath DN | M20: Bhootnath DN | N20: Bhootnath DN
A21: TRAIN NO. | B21: 201 | C21: 201 | D21: 201 | E21: 201 | F21: 201 | G21: 201 | H21: 201 | I21: 201 | J21: 201 | K21: 201 | L21: 201 | M21: 201 | N21: 201
A22: STATION | B22: UP DOT | C22: UP DOT | D22: UP DOT | E22: UP DOT | F22: UP DOT | G22: UP DOT | H22: UP DOT | I22: UP DOT | J22: UP DOT | K22: UP DOT | L22: UP DOT | M22: UP DOT | N22: UP DOT
A23: BHOOTNATH | B23: =B19+'L-7 KEY MKPR- JPVE(FINAL)'!$N$10 -> 0.58333333 | C23: =C19+'L-7 KEY MKPR- JPVE(FINAL)'!$N$10 -> 0.60416667 | D23: =D19+'L-7 KEY MKPR- JPVE(FINAL)'!$N$10 -> 0.625 | E23: =E19+'L-7 KEY MKPR- JPVE(FINAL)'!$N$10 -> 0.64583333 | F23: =F19+'L-7 KEY MKPR- JPVE(FINAL)'!$N$10 -> 0.66666667 | G23: =G19+'L-7 KEY MKPR- JPVE(FINAL)'!$N$10 -> 0.6875 | H23: =H19+'L-7 KEY MKPR- JPVE(FINAL)'!$N$10 -> 0.70833333 | I23: =I19+'L-7 KEY MKPR- JPVE(FINAL)'!$N$10 -> 0.72916667 | ... N23: =N19+'L-7 KEY MKPR- JPVE(FINAL)'!$N$10 -> 0.83333333
A24: ZERO MILE | B24: =B23+'L-7 KEY MKPR- JPVE(FINAL)'!$J5 -> 0.58685185 | C24: =C23+'L-7 KEY MKPR- JPVE(FINAL)'!$J5 -> 0.60768519 | D24: =D23+'L-7 KEY MKPR- JPVE(FINAL)'!$J5 -> 0.62851852 | E24: =E23+'L-7 KEY MKPR- JPVE(FINAL)'!$J5 -> 0.64935185 | F24: =F23+'L-7 KEY MKPR- JPVE(FINAL)'!$J5 -> 0.67018519 | G24: =G23+'L-7 KEY MKPR- JPVE(FINAL)'!$J5 -> 0.69101852 | H24: =H23+'L-7 KEY MKPR- JPVE(FINAL)'!$J5 -> 0.71185185 | I24: =I23+'L-7 KEY MKPR- JPVE(FINAL)'!$J5 -> 0.73268519 | ... N24: =N23+'L-7 KEY MKPR- JPVE(FINAL)'!$J5 -> 0.83685185
A25: PATLIPUTRA | B25: =B24+'L-7 KEY MKPR- JPVE(FINAL)'!$J6 -> 0.59018519 | C25: =C24+'L-7 KEY MKPR- JPVE(FINAL)'!$J6 -> 0.61101852 | D25: =D24+'L-7 KEY MKPR- JPVE(FINAL)'!$J6 -> 0.63185185 | E25: =E24+'L-7 KEY MKPR- JPVE(FINAL)'!$J6 -> 0.65268519 | F25: =F24+'L-7 KEY MKPR- JPVE(FINAL)'!$J6 -> 0.67351852 | G25: =G24+'L-7 KEY MKPR- JPVE(FINAL)'!$J6 -> 0.69435185 | H25: =H24+'L-7 KEY MKPR- JPVE(FINAL)'!$J6 -> 0.71518519 | I25: =I24+'L-7 KEY MKPR- JPVE(FINAL)'!$J6 -> 0.73601852 | ... N25: =N24+'L-7 KEY MKPR- JPVE(FINAL)'!$J6 -> 0.84018519
A26: REVERSAL FROM | B26: Patliputra DN | C26: Patliputra DN | D26: Patliputra DN | E26: Patliputra DN | F26: Patliputra DN | G26: Patliputra DN | H26: Patliputra DN | I26: Patliputra DN | J26: Patliputra DN | K26: Patliputra DN | L26: Patliputra DN | M26: Patliputra DN | N26: Patliputra DN
K28: TOTAL TRIPS & KMS IN TIME-TABLE
K29: SECTION | L29: KMS | M29: NO.OF TRIPS | N29: TOTAL KM's | Q29: HEADWAY
K30: PPBT-BHOOT | L30: 2.76 | M30: 24 | N30: =L30*M30 -> 66.24 | Q30: 17 MIN
K31: BHOOT -PPBT | L31: 2.76 | M31: 25 | N31: =L31*M31 -> 69
K32: TOTAL | M32: =M30+M31 -> 49 | N32: =N30+N31 -> 135.24 | Q32: REVERSAL TIME AT MKPR DN & JPVE DN PF | T32: DWELL TIME AT JRMR & BURI
K33: FIRST AND LAST TRAIN TIMINGS
K34: FROM | L34: TO | M34: FIRST TRAIN | N34: LAST TRAIN | Q34: 1 MIN 30 SECS | T34: 40 SECS
K35: PPBT | L35: BHOOT | M35: 0.34375 | N35: 0.82291667
K36: BHOOT | L36: PPBT | M36: 0.33333333 | N36: 0.83333333
K37: HEADWAY, DWELL TIME AND REVERSAL TIME
K38: HEADWAY | N38: 30 MINS | R38: 799 | S38: DN LINE
K39: REVERSAL TIME AT PPBT AND BHOONATH | N39: 5 MIN 08 SEC | R39: 798 | S39: UP LINE
K40: DWELL TIME AT ZERO MILE | N40: 40 SEC

Sheet MKPR-JPVE UP OR DN
A1: MKPR-JPVE SECTION MONDAY- SUNDAY TIME TABLE (Draft)
A2: TRAIN NO. | B2: 799 | C2: 798 | D2: 799 | E2: 798 | F2: 799 | G2: 798 | H2: 799 | I2: 798 | J2: 799 | K2: 798 | L2: 799 | M2: 798 | N2: 799
B3: UP LINE | C3: DN LINE | D3: UP LINE | E3: DN LINE | F3: UP LINE | G3: DN LINE | H3: UP LINE | I3: DN LINE | J3: UP LINE | K3: DN LINE | L3: UP LINE | M3: DN LINE | N3: UP LINE
A4: JPVE | B4: REVENUE PILOTING FROM JPVE UP TO MKPR UP @25KMPH | C4: REVENUE PILOTING FROM MKPR DN TO JPVE DN @25KMPH | D4: 0.33333333 | E4: 0.34652778 | F4: =E4+'L-7 KEY MKPR- JPVE(FINAL)'!$O$9 -> 0.37013889 | G4: =F4+'L-7 KEY MKPR- JPVE(FINAL)'!$O$9 -> 0.39375 | H4: =G4+'L-7 KEY MKPR- JPVE(FINAL)'!$O$9 -> 0.41736111 | I4: =H4+'L-7 KEY MKPR- JPVE(FINAL)'!$O$9 -> 0.44097222 | J4: =I4+'L-7 KEY MKPR- JPVE(FINAL)'!$O$9 -> 0.46458333 | K4: =J4+'L-7 KEY MKPR- JPVE(FINAL)'!$O$9 -> 0.48819444 | L4: =K4+'L-7 KEY MKPR- JPVE(FINAL)'!$O$9 -> 0.51180556 | M4: =L4+'L-7 KEY MKPR- JPVE(FINAL)'!$O$9 -> 0.53541667 | N4: =M4+'L-7 KEY MKPR- JPVE(FINAL)'!$O$9 -> 0.55902778 | R4: =E5-E4 -> 0.0023611111
A5: JRMR | D5: =D4+'L-7 KEY MKPR- JPVE(FINAL)'!$F5 -> 0.3412963 | E5: =E4+'L-7 KEY NEW(JPVE)'!$D5 -> 0.34888889 | F5: =F4+'L-7 KEY NEW(JPVE)'!$D5 -> 0.3725 | G5: =G4+'L-7 KEY NEW(JPVE)'!$D5 -> 0.39611111 | H5: =H4+'L-7 KEY NEW(JPVE)'!$D5 -> 0.41972222 | I5: =I4+'L-7 KEY NEW(JPVE)'!$D5 -> 0.44333333 | J5: =J4+'L-7 KEY NEW(JPVE)'!$D5 -> 0.46694444 | K5: =K4+'L-7 KEY NEW(JPVE)'!$D5 -> 0.49055556 | L5: =L4+'L-7 KEY NEW(JPVE)'!$D5 -> 0.51416667 | ... N5: =N4+'L-7 KEY NEW(JPVE)'!$D5 -> 0.56138889 | R5: =E6-E5 -> 0.0030324074
A6: BURI | D6: =D5+'L-7 KEY MKPR- JPVE(FINAL)'!$F6 -> 0.3481713 | E6: =E5+'L-7 KEY NEW(JPVE)'!$D6 -> 0.3519213 | F6: =F5+'L-7 KEY NEW(JPVE)'!$D6 -> 0.37553241 | G6: =G5+'L-7 KEY NEW(JPVE)'!$D6 -> 0.39914352 | H6: =H5+'L-7 KEY NEW(JPVE)'!$D6 -> 0.42275463 | I6: =I5+'L-7 KEY NEW(JPVE)'!$D6 -> 0.44636574 | J6: =J5+'L-7 KEY NEW(JPVE)'!$D6 -> 0.46997685 | K6: =K5+'L-7 KEY NEW(JPVE)'!$D6 -> 0.49358796 | L6: =L5+'L-7 KEY NEW(JPVE)'!$D6 -> 0.51719907 | ... N6: =N5+'L-7 KEY NEW(JPVE)'!$D6 -> 0.5644213 | R6: =E7-E6 -> 0.0053703704
A7: MKPR | D7: =D6+'L-7 KEY MKPR- JPVE(FINAL)'!$F7 -> 0.3481713 | E7: =E6+'L-7 KEY NEW(JPVE)'!$D7 -> 0.35729167 | F7: =F6+'L-7 KEY NEW(JPVE)'!$D7 -> 0.38090278 | G7: =G6+'L-7 KEY NEW(JPVE)'!$D7 -> 0.40451389 | H7: =H6+'L-7 KEY NEW(JPVE)'!$D7 -> 0.428125 | I7: =I6+'L-7 KEY NEW(JPVE)'!$D7 -> 0.45173611 | J7: =J6+'L-7 KEY NEW(JPVE)'!$D7 -> 0.47534722 | K7: =K6+'L-7 KEY NEW(JPVE)'!$D7 -> 0.49895833 | L7: =L6+'L-7 KEY NEW(JPVE)'!$D7 -> 0.52256944 | ... N7: =N6+'L-7 KEY NEW(JPVE)'!$D7 -> 0.56979167
A8: REVERSAL FROM | B8: MKPR UP | C8: MKPR DN | D8: MKPR UP | E8: MKPR DN | F8: MKPR UP | G8: MKPR DN | H8: MKPR UP | I8: MKPR DN | J8: MKPR UP | K8: MKPR DN | L8: MKPR UP | M8: MKPR DN | N8: MKPR UP
A9: TRAIN NO | C9: =C2 -> 798 | D9: =D2 -> 799 | E9: =E2 -> 798 | F9: =F2 -> 799 | G9: =G2 -> 798 | H9: =H2 -> 799 | I9: 798 | J9: =J2 -> 799 | K9: 798 | L9: =L2 -> 799 | M9: 798 | N9: =N2 -> 799 | R9: =D11-D10 -> 0.0046180556
A10: MKPR | C10: 0.33333333 | D10: 0.346875 | E10: 0.35868056 | F10: =F7+'L-7 KEY MKPR- JPVE(FINAL)'!$N$10 -> 0.38446759 | G10: =G7+'L-7 KEY MKPR- JPVE(FINAL)'!$N$10 -> 0.4080787 | H10: =H7+'L-7 KEY MKPR- JPVE(FINAL)'!$N$10 -> 0.43168981 | I10: =I7+'L-7 KEY MKPR- JPVE(FINAL)'!$N$10 -> 0.45530093 | J10: =J7+'L-7 KEY MKPR- JPVE(FINAL)'!$N$10 -> 0.47891204 | K10: =K7+'L-7 KEY MKPR- JPVE(FINAL)'!$N$10 -> 0.50252315 | L10: =L7+'L-7 KEY MKPR- JPVE(FINAL)'!$N$10 -> 0.52613426 | M10: =M7+'L-7 KEY MKPR- JPVE(FINAL)'!$N$10 -> 0.54974537 | N10: =N7+'L-7 KEY MKPR- JPVE(FINAL)'!$N$10 -> 0.57335648 | R10: =D12-D11 -> 0.0030324074
A11: BURI | C11: =C10+'L-7 KEY MKPR- JPVE(FINAL)'!$L5 -> 0.33891204 | D11: =D10+'L-7 KEY NEW(JPVE)'!$M5 -> 0.35149306 | E11: =E10+'L-7 KEY NEW(JPVE)'!$M5 -> 0.36329861 | F11: =F10+'L-7 KEY NEW(JPVE)'!$M5 -> 0.38908565 | G11: =G10+'L-7 KEY NEW(JPVE)'!$M5 -> 0.41269676 | H11: =H10+'L-7 KEY NEW(JPVE)'!$M5 -> 0.43630787 | I11: =I10+'L-7 KEY NEW(JPVE)'!$M5 -> 0.45991898 | J11: =J10+'L-7 KEY NEW(JPVE)'!$M5 -> 0.48353009 | K11: =K10+'L-7 KEY NEW(JPVE)'!$M5 -> 0.5071412 | ... N11: =N10+'L-7 KEY NEW(JPVE)'!$M5 -> 0.57797454 | R11: =D13-D12 -> 0.0018981481
A12: JRMR | C12: =C11+'L-7 KEY MKPR- JPVE(FINAL)'!$L6 -> 0.34240741 | D12: =D11+'L-7 KEY NEW(JPVE)'!$M6 -> 0.35452546 | E12: =E11+'L-7 KEY NEW(JPVE)'!$M6 -> 0.36633102 | F12: =F11+'L-7 KEY NEW(JPVE)'!$M6 -> 0.39211806 | G12: =G11+'L-7 KEY NEW(JPVE)'!$M6 -> 0.41572917 | H12: =H11+'L-7 KEY NEW(JPVE)'!$M6 -> 0.43934028 | I12: =I11+'L-7 KEY NEW(JPVE)'!$M6 -> 0.46295139 | J12: =J11+'L-7 KEY NEW(JPVE)'!$M6 -> 0.4865625 | K12: =K11+'L-7 KEY NEW(JPVE)'!$M6 -> 0.51017361 | ... N12: =N11+'L-7 KEY NEW(JPVE)'!$M6 -> 0.58100694 | S12: 10
A13: JPVE | C13: =C12+'L-7 KEY MKPR- JPVE(FINAL)'!$L7 -> 0.34502315 | D13: =D12+'L-7 KEY NEW(JPVE)'!$M7 -> 0.35642361 | E13: =E12+'L-7 KEY NEW(JPVE)'!$M7 -> 0.36822917 | F13: =F12+'L-7 KEY NEW(JPVE)'!$M7 -> 0.3940162 | G13: =G12+'L-7 KEY NEW(JPVE)'!$M7 -> 0.41762731 | H13: =H12+'L-7 KEY NEW(JPVE)'!$M7 -> 0.44123843 | I13: =I12+'L-7 KEY NEW(JPVE)'!$M7 -> 0.46484954 | J13: =J12+'L-7 KEY NEW(JPVE)'!$M7 -> 0.48846065 | K13: =K12+'L-7 KEY NEW(JPVE)'!$M7 -> 0.51207176 | ... N13: =N12+'L-7 KEY NEW(JPVE)'!$M7 -> 0.58290509 | S13: 24
A14: REVERSAL FROM | C14: JPVE DN | D14: JPVE UP | E14: JPVE DN | F14: JPVE UP | G14: JPVE DN | H14: JPVE UP | I14: JPVE DN | J14: JPVE UP | K14: JPVE DN | L14: JPVE UP | M14: JPVE DN | N14: JPVE UP | S14: 5
R15: =E7-E6 -> 0.0053703704 | S15: 39
A16: TRAIN NO. | B16: =M2 -> 798 | C16: =N2 -> 799 | D16: =B16 -> 798 | E16: =C16 -> 799 | F16: =D16 -> 798 | G16: =E16 -> 799 | H16: =F16 -> 798 | I16: =G16 -> 799 | J16: =H16 -> 798 | K16: =I16 -> 799 | ... N16: =L16 -> 798
B17: DN LINE | C17: UP LINE | D17: DN LINE | E17: UP LINE | F17: DN LINE | G17: UP LINE | H17: DN LINE | I17: UP LINE | J17: DN LINE | K17: UP LINE | L17: DN LINE | M17: UP LINE | N17: DN LINE
A18: JPVE | B18: =N4+'L-7 KEY MKPR- JPVE(FINAL)'!$O$9 -> 0.58263889 | C18: =B18+'L-7 KEY MKPR- JPVE(FINAL)'!$O$9 -> 0.60625 | D18: =C18+'L-7 KEY MKPR- JPVE(FINAL)'!$O$9 -> 0.62986111 | E18: =D18+'L-7 KEY MKPR- JPVE(FINAL)'!$O$9 -> 0.65347222 | F18: =E18+'L-7 KEY MKPR- JPVE(FINAL)'!$O$9 -> 0.67708333 | G18: =F18+'L-7 KEY MKPR- JPVE(FINAL)'!$O$9 -> 0.70069444 | H18: =G18+'L-7 KEY MKPR- JPVE(FINAL)'!$O$9 -> 0.72430556 | I18: =H18+'L-7 KEY MKPR- JPVE(FINAL)'!$O$9 -> 0.74791667 | J18: =I18+'L-7 KEY MKPR- JPVE(FINAL)'!$O$9 -> 0.77152778 | ... N18: =M18+'L-7 KEY MKPR- JPVE(FINAL)'!$O$9 -> 0.86597222 | R18: =E13-E10 -> 0.0095486111
A19: JRMR | B19: =B18+'L-7 KEY NEW(JPVE)'!$D5 -> 0.585 | C19: =C18+'L-7 KEY NEW(JPVE)'!$D5 -> 0.60861111 | D19: =D18+'L-7 KEY NEW(JPVE)'!$D5 -> 0.63222222 | E19: =E18+'L-7 KEY NEW(JPVE)'!$D5 -> 0.65583333 | F19: =F18+'L-7 KEY NEW(JPVE)'!$D5 -> 0.67944444 | G19: =G18+'L-7 KEY NEW(JPVE)'!$D5 -> 0.70305556 | H19: =H18+'L-7 KEY NEW(JPVE)'!$D5 -> 0.72666667 | I19: =I18+'L-7 KEY NEW(JPVE)'!$D5 -> 0.75027778 | ... N19: =N18+'L-7 KEY NEW(JPVE)'!$D5 -> 0.86833333
A20: BURI | B20: =B19+'L-7 KEY NEW(JPVE)'!$D6 -> 0.58803241 | C20: =C19+'L-7 KEY NEW(JPVE)'!$D6 -> 0.61164352 | D20: =D19+'L-7 KEY NEW(JPVE)'!$D6 -> 0.63525463 | E20: =E19+'L-7 KEY NEW(JPVE)'!$D6 -> 0.65886574 | F20: =F19+'L-7 KEY NEW(JPVE)'!$D6 -> 0.68247685 | G20: =G19+'L-7 KEY NEW(JPVE)'!$D6 -> 0.70608796 | H20: =H19+'L-7 KEY NEW(JPVE)'!$D6 -> 0.72969907 | I20: =I19+'L-7 KEY NEW(JPVE)'!$D6 -> 0.75331019 | ... N20: =N19+'L-7 KEY NEW(JPVE)'!$D6 -> 0.87136574
A21: MKPR | B21: =B20+'L-7 KEY NEW(JPVE)'!$D7 -> 0.59340278 | C21: =C20+'L-7 KEY NEW(JPVE)'!$D7 -> 0.61701389 | D21: =D20+'L-7 KEY NEW(JPVE)'!$D7 -> 0.640625 | E21: =E20+'L-7 KEY NEW(JPVE)'!$D7 -> 0.66423611 | F21: =F20+'L-7 KEY NEW(JPVE)'!$D7 -> 0.68784722 | G21: =G20+'L-7 KEY NEW(JPVE)'!$D7 -> 0.71145833 | H21: =H20+'L-7 KEY NEW(JPVE)'!$D7 -> 0.73506944 | I21: =I20+'L-7 KEY NEW(JPVE)'!$D7 -> 0.75868056 | ... N21: =N20+'L-7 KEY NEW(JPVE)'!$D7 -> 0.87673611
A22: REVERSAL FROM | B22: MKPR DN | C22: MKPR UP | D22: MKPR DN | E22: MKPR UP | F22: MKPR DN | G22: MKPR UP | H22: MKPR DN | I22: MKPR UP | J22: MKPR DN | K22: MKPR UP | L22: MKPR DN | M22: MKPR UP | N22: MKPR DN | R22: =F7-F4 -> 0.010763889
A23: TRAIN NO | B23: 798 | C23: =C16 -> 799 | D23: 798 | E23: =E16 -> 799 | F23: 798 | G23: =G16 -> 799 | H23: 798 | I23: =I16 -> 799 | J23: 798 | K23: =K16 -> 799 | L23: 798 | M23: =M16 -> 799 | N23: 798
A24: MKPR | B24: =B21+'L-7 KEY MKPR- JPVE(FINAL)'!$N$10 -> 0.59696759 | C24: =C21+'L-7 KEY MKPR- JPVE(FINAL)'!$N$10 -> 0.6205787 | D24: =D21+'L-7 KEY MKPR- JPVE(FINAL)'!$N$10 -> 0.64418981 | E24: =E21+'L-7 KEY MKPR- JPVE(FINAL)'!$N$10 -> 0.66780093 | F24: =F21+'L-7 KEY MKPR- JPVE(FINAL)'!$N$10 -> 0.69141204 | G24: =G21+'L-7 KEY MKPR- JPVE(FINAL)'!$N$10 -> 0.71502315 | H24: =H21+'L-7 KEY MKPR- JPVE(FINAL)'!$N$10 -> 0.73863426 | I24: =I21+'L-7 KEY MKPR- JPVE(FINAL)'!$N$10 -> 0.76224537 | ... N24: =N21+'L-7 KEY MKPR- JPVE(FINAL)'!$N$10 -> 0.88030093
A25: BURI | B25: =B24+'L-7 KEY NEW(JPVE)'!$M5 -> 0.60158565 | C25: =C24+'L-7 KEY NEW(JPVE)'!$M5 -> 0.62519676 | D25: =D24+'L-7 KEY NEW(JPVE)'!$M5 -> 0.64880787 | E25: =E24+'L-7 KEY NEW(JPVE)'!$M5 -> 0.67241898 | F25: =F24+'L-7 KEY NEW(JPVE)'!$M5 -> 0.69603009 | G25: =G24+'L-7 KEY NEW(JPVE)'!$M5 -> 0.7196412 | H25: =H24+'L-7 KEY NEW(JPVE)'!$M5 -> 0.74325231 | I25: =I24+'L-7 KEY NEW(JPVE)'!$M5 -> 0.76686343 | ... N25: =N24+'L-7 KEY NEW(JPVE)'!$M5 -> 0.88491898
A26: JRMR | B26: =B25+'L-7 KEY NEW(JPVE)'!$M6 -> 0.60461806 | C26: =C25+'L-7 KEY NEW(JPVE)'!$M6 -> 0.62822917 | D26: =D25+'L-7 KEY NEW(JPVE)'!$M6 -> 0.65184028 | E26: =E25+'L-7 KEY NEW(JPVE)'!$M6 -> 0.67545139 | F26: =F25+'L-7 KEY NEW(JPVE)'!$M6 -> 0.6990625 | G26: =G25+'L-7 KEY NEW(JPVE)'!$M6 -> 0.72267361 | H26: =H25+'L-7 KEY NEW(JPVE)'!$M6 -> 0.74628472 | I26: =I25+'L-7 KEY NEW(JPVE)'!$M6 -> 0.76989583 | ... N26: =N25+'L-7 KEY NEW(JPVE)'!$M6 -> 0.88795139
A27: JPVE | B27: =B26+'L-7 KEY NEW(JPVE)'!$M7 -> 0.6065162 | C27: =C26+'L-7 KEY NEW(JPVE)'!$M7 -> 0.63012731 | D27: =D26+'L-7 KEY NEW(JPVE)'!$M7 -> 0.65373843 | E27: =E26+'L-7 KEY NEW(JPVE)'!$M7 -> 0.67734954 | F27: =F26+'L-7 KEY NEW(JPVE)'!$M7 -> 0.70096065 | G27: =G26+'L-7 KEY NEW(JPVE)'!$M7 -> 0.72457176 | H27: =H26+'L-7 KEY NEW(JPVE)'!$M7 -> 0.74818287 | I27: =I26+'L-7 KEY NEW(JPVE)'!$M7 -> 0.77179398 | ... N27: =N26+'L-7 KEY NEW(JPVE)'!$M7 -> 0.88984954
A28: REVERSAL FROM | B28: JPVE DN | C28: JPVE UP | D28: JPVE DN | E28: JPVE UP | F28: JPVE DN | G28: JPVE UP | H28: JPVE DN | I28: JPVE UP | J28: JPVE DN | K28: JPVE UP | L28: JPVE DN | M28: JPVE UP | N28: JPVE DN
A30: TRAIN NO. | B30: =M16 -> 799 | C30: =N16 -> 798 | D30: =B30 -> 799 | E30: =C30 -> 798 | F30: =D30 -> 799 | G30: =E30 -> 798 | H30: =F30 -> 799 | I30: =G30 -> 798 | J30: =H30 -> 799 | K30: =I30 -> 798 | ... N30: =L30 -> 799
B31: UP LINE | C31: DN LINE | D31: UP LINE | E31: DN LINE | F31: UP LINE | G31: DN LINE | H31: UP LINE | I31: DN LINE | J31: UP LINE | K31: DN LINE | L31: UP LINE | M31: DN LINE | N31: UP LINE | R31: =C35-C34 -> 0.0053703704
A32: JPVE | B32: =N18+'L-7 KEY MKPR- JPVE(FINAL)'!$O$9 -> 0.88958333 | C32: =B32+'L-7 KEY MKPR- JPVE(FINAL)'!$O$9 -> 0.91319444 | D32: =C32+'L-7 KEY MKPR- JPVE(FINAL)'!$O$9 -> 0.93680556 | E32: =D32+'L-7 KEY MKPR- JPVE(FINAL)'!$O$9 -> 0.96041667 | F32: =E32+'L-7 KEY MKPR- JPVE(FINAL)'!$O$9 -> 0.98402778 | G32: =F32+'L-7 KEY MKPR- JPVE(FINAL)'!$O$9 -> 1.0076389 | H32: =G32+'L-7 KEY MKPR- JPVE(FINAL)'!$O$9 -> 1.03125 | I32: =H32+'L-7 KEY MKPR- JPVE(FINAL)'!$O$9 -> 1.0548611 | J32: =I32+'L-7 KEY MKPR- JPVE(FINAL)'!$O$9 -> 1.0784722 | ... N32: =M32+'L-7 KEY MKPR- JPVE(FINAL)'!$O$9 -> 1.1729167
A33: JRMR | B33: =B32+'L-7 KEY NEW(JPVE)'!$D5 -> 0.89194444 | C33: =C32+'L-7 KEY NEW(JPVE)'!$D5 -> 0.91555556 | D33: =D32+'L-7 KEY NEW(JPVE)'!$D5 -> 0.93916667 | E33: =E32+'L-7 KEY NEW(JPVE)'!$D5 -> 0.96277778 | F33: =F32+'L-7 KEY NEW(JPVE)'!$D5 -> 0.98638889 | G33: =G32+'L-7 KEY NEW(JPVE)'!$D5 -> 1.01 | H33: =H32+'L-7 KEY NEW(JPVE)'!$D5 -> 1.0336111 | I33: =I32+'L-7 KEY NEW(JPVE)'!$D5 -> 1.0572222 | ... N33: =N32+'L-7 KEY NEW(JPVE)'!$D5 -> 1.1752778
A34: BURI | B34: =B33+'L-7 KEY NEW(JPVE)'!$D6 -> 0.89497685 | C34: =C33+'L-7 KEY NEW(JPVE)'!$D6 -> 0.91858796 | D34: =D33+'L-7 KEY NEW(JPVE)'!$D6 -> 0.94219907 | E34: =E33+'L-7 KEY NEW(JPVE)'!$D6 -> 0.96581019 | F34: =F33+'L-7 KEY NEW(JPVE)'!$D6 -> 0.9894213 | G34: =G33+'L-7 KEY NEW(JPVE)'!$D6 -> 1.0130324 | H34: =H33+'L-7 KEY NEW(JPVE)'!$D6 -> 1.0366435 | I34: =I33+'L-7 KEY NEW(JPVE)'!$D6 -> 1.0602546 | ... N34: =N33+'L-7 KEY NEW(JPVE)'!$D6 -> 1.1783102
A35: MKPR | B35: =B34+'L-7 KEY NEW(JPVE)'!$D7 -> 0.90034722 | C35: =C34+'L-7 KEY NEW(JPVE)'!$D7 -> 0.92395833 | D35: =D34+'L-7 KEY NEW(JPVE)'!$D7 -> 0.94756944 | E35: =E34+'L-7 KEY NEW(JPVE)'!$D7 -> 0.97118056 | F35: =F34+'L-7 KEY NEW(JPVE)'!$D7 -> 0.99479167 | G35: =G34+'L-7 KEY NEW(JPVE)'!$D7 -> 1.0184028 | H35: =H34+'L-7 KEY NEW(JPVE)'!$D7 -> 1.0420139 | I35: =I34+'L-7 KEY NEW(JPVE)'!$D7 -> 1.065625 | ... N35: =N34+'L-7 KEY NEW(JPVE)'!$D7 -> 1.1836806
A36: REVERSAL FROM | B36: MKPR UP | C36: MKPR DN | D36: MKPR UP | E36: MKPR DN | F36: MKPR UP | G36: MKPR DN | H36: MKPR UP | I36: MKPR DN | J36: MKPR UP | K36: MKPR DN | L36: MKPR UP | M36: MKPR DN | N36: MKPR UP
A37: TRAIN NO | B37: =B30 -> 799 | C37: =C30 -> 798 | D37: =D30 -> 799 | E37: =E30 -> 798 | F37: =F30 -> 799 | G37: =G30 -> 798 | H37: =H30 -> 799 | I37: =I30 -> 798 | ... N37: =N30 -> 799
A38: MKPR | B38: =B35+'L-7 KEY MKPR- JPVE(FINAL)'!$N$10 -> 0.90391204 | C38: =C35+'L-7 KEY MKPR- JPVE(FINAL)'!$N$10 -> 0.92752315 | D38: =D35+'L-7 KEY MKPR- JPVE(FINAL)'!$N$10 -> 0.95113426 | E38: =E35+'L-7 KEY MKPR- JPVE(FINAL)'!$N$10 -> 0.97474537 | F38: =F35+'L-7 KEY MKPR- JPVE(FINAL)'!$N$10 -> 0.99835648 | G38: =G35+'L-7 KEY MKPR- JPVE(FINAL)'!$N$10 -> 1.0219676 | H38: =H35+'L-7 KEY MKPR- JPVE(FINAL)'!$N$10 -> 1.0455787 | I38: =I35+'L-7 KEY MKPR- JPVE(FINAL)'!$N$10 -> 1.0691898 | ... N38: =N35+'L-7 KEY MKPR- JPVE(FINAL)'!$N$10 -> 1.1872454
A39: BURI | B39: =B38+'L-7 KEY NEW(JPVE)'!$M5 -> 0.90853009 | C39: =C38+'L-7 KEY NEW(JPVE)'!$M5 -> 0.9321412 | D39: =D38+'L-7 KEY NEW(JPVE)'!$M5 -> 0.95575231 | E39: =E38+'L-7 KEY NEW(JPVE)'!$M5 -> 0.97936343 | F39: =F38+'L-7 KEY NEW(JPVE)'!$M5 -> 1.0029745 | G39: =G38+'L-7 KEY NEW(JPVE)'!$M5 -> 1.0265856 | H39: =H38+'L-7 KEY NEW(JPVE)'!$M5 -> 1.0501968 | I39: =I38+'L-7 KEY NEW(JPVE)'!$M5 -> 1.0738079 | ... N39: =N38+'L-7 KEY NEW(JPVE)'!$M5 -> 1.1918634
A40: JRMR | B40: =B39+'L-7 KEY NEW(JPVE)'!$M6 -> 0.9115625 | C40: =C39+'L-7 KEY NEW(JPVE)'!$M6 -> 0.93517361 | D40: =D39+'L-7 KEY NEW(JPVE)'!$M6 -> 0.95878472 | E40: =E39+'L-7 KEY NEW(JPVE)'!$M6 -> 0.98239583 | F40: =F39+'L-7 KEY NEW(JPVE)'!$M6 -> 1.0060069 | G40: =G39+'L-7 KEY NEW(JPVE)'!$M6 -> 1.0296181 | H40: =H39+'L-7 KEY NEW(JPVE)'!$M6 -> 1.0532292 | I40: =I39+'L-7 KEY NEW(JPVE)'!$M6 -> 1.0768403 | ... N40: =N39+'L-7 KEY NEW(JPVE)'!$M6 -> 1.1948958 | R40: =C49-C48 -> 0.0053703704
A41: JPVE | B41: =B40+'L-7 KEY NEW(JPVE)'!$M7 -> 0.91346065 | C41: =C40+'L-7 KEY NEW(JPVE)'!$M7 -> 0.93707176 | D41: =D40+'L-7 KEY NEW(JPVE)'!$M7 -> 0.96068287 | E41: =E40+'L-7 KEY NEW(JPVE)'!$M7 -> 0.98429398 | F41: =F40+'L-7 KEY NEW(JPVE)'!$M7 -> 1.0079051 | G41: =G40+'L-7 KEY NEW(JPVE)'!$M7 -> 1.0315162 | H41: =H40+'L-7 KEY NEW(JPVE)'!$M7 -> 1.0551273 | I41: =I40+'L-7 KEY NEW(JPVE)'!$M7 -> 1.0787384 | ... N41: =N40+'L-7 KEY NEW(JPVE)'!$M7 -> 1.196794
...

Sheet MKPR-JPVE LOOP MULTI PAGE
A1: TRAIN NO. | B1: 799 | C1: 799 | D1: 799 | E1: 799 | F1: 799 | G1: 799 | H1: 799 | I1: 799 | J1: 799 | K1: 799 | L1: 799 | M1: 799 | N1: 799 | O1: 719 | P1: 715 | Q1: 705 | R1: 711 | S1: 701 | T1: 724 | U1: 725 | V1: 702 | W1: 726 | X1: 710 | Y1: 727 | Z1: 716 | AA1: 728 | AB1: 737 | AC1: 720 | AD1: 730 | AE1: 721 | AF1: 731 | AG1: 722
B2: JPVE DN
A3: NEW ISBT | B3: 0.22916667 | C3: 0.33333333 | D3: =#REF!+'L-7 KEY NEW(JPVE)'!$T$20 -> #REF! | E3: =#REF!+'L-7 KEY NEW(JPVE)'!$T$20 -> #REF! | F3: =#REF!+'L-7 KEY NEW(JPVE)'!$T$20 -> #REF! | G3: =#REF!+'L-7 KEY NEW(JPVE)'!$T$20 -> #REF! | H3: =#REF!+'L-7 KEY NEW(JPVE)'!$T$20 -> #REF! | I3: =#REF!+'L-7 KEY NEW(JPVE)'!$T$20 -> #REF! | J3: =#REF!+'L-7 KEY NEW(JPVE)'!$T$20 -> #REF! | K3: =#REF!+'L-7 KEY NEW(JPVE)'!$T$20 -> #REF! | ... AG3: =#REF!+'L-7 KEY NEW(JPVE)'!$T$20 -> #REF!
A4: ZERO MILE | B4: =B3+'L-7 KEY NEW(JPVE)'!$I5 -> 0.23212963 | C4: =C3+'L-7 KEY NEW(JPVE)'!$D63 -> 0.3362963 | D4: =D3+'L-7 KEY NEW(JPVE)'!$D5 -> #REF! | E4: =E3+'L-7 KEY NEW(JPVE)'!$D5 -> #REF! | F4: =F3+'L-7 KEY NEW(JPVE)'!$D5 -> #REF! | G4: =G3+'L-7 KEY NEW(JPVE)'!$D5 -> #REF! | H4: =H3+'L-7 KEY NEW(JPVE)'!$D5 -> #REF! | I4: =I3+'L-7 KEY NEW(JPVE)'!$D5 -> #REF! | J4: =J3+'L-7 KEY NEW(JPVE)'!$D5 -> #REF! | K4: =K3+'L-7 KEY NEW(JPVE)'!$D5 -> #REF! | ... AG4: =AG3+'L-7 KEY NEW(JPVE)'!$D5 -> #REF!
A5: BHOOTNATH | B5: =B4+'L-7 KEY NEW(JPVE)'!$I6 -> 0.23597222 | C5: =C4+'L-7 KEY NEW(JPVE)'!$D64 -> 0.33903935 | D5: =E4+'L-7 KEY NEW(JPVE)'!$D6 -> #REF! | E5: =F4+'L-7 KEY NEW(JPVE)'!$D6 -> #REF! | F5: =G4+'L-7 KEY NEW(JPVE)'!$D6 -> #REF! | G5: =H4+'L-7 KEY NEW(JPVE)'!$D6 -> #REF! | H5: =I4+'L-7 KEY NEW(JPVE)'!$D6 -> #REF! | I5: =J4+'L-7 KEY NEW(JPVE)'!$D6 -> #REF! | J5: =K4+'L-7 KEY NEW(JPVE)'!$D6 -> #REF! | K5: =L4+'L-7 KEY NEW(JPVE)'!$D6 -> #REF! | ... AF5: =AG4+'L-7 KEY NEW(JPVE)'!$D6 -> #REF!
A6: REVERSAL FROM | B6: MKPR DN | C6: MKPR DN | D6: MKPR DN | E6: MKPR DN | F6: MKPR DN | G6: MKPR DN | H6: MKPR DN | I6: MKPR DN | J6: MKPR DN | K6: MKPR DN | L6: MKPR DN | M6: MKPR DN | N6: MKPR DN | O6: MKPR DN | P6: MKPR DN | Q6: MKPR DN | R6: MKPR DN | S6: MKPR DN | T6: MKPR DN | U6: MKPR DN | V6: MKPR DN | W6: MKPR DN | X6: MKPR DN | Y6: MKPR DN | Z6: MKPR DN | AA6: MKPR DN | AB6: MKPR DN | AC6: MKPR DN | AD6: MKPR DN | AE6: MKPR DN | AF6: MKPR DN | AG6: MKPR DN
A7: TRAIN NO | B7: =B1 -> 799 | C7: =C1 -> 799 | D7: =D1 -> 799 | E7: =E1 -> 799 | F7: =F1 -> 799 | G7: =G1 -> 799 | H7: =H1 -> 799 | I7: =I1 -> 799 | ... AG7: =AG1 -> 722
A8: BHOOTNATH | B8: 0.25 | C8: =#REF!+'L-7 KEY NEW(JPVE)'!$T$20 -> #REF! | D8: =#REF!+'L-7 KEY NEW(JPVE)'!$T$20 -> #REF! | E8: =#REF!+'L-7 KEY NEW(JPVE)'!$T$20 -> #REF! | F8: =#REF!+'L-7 KEY NEW(JPVE)'!$T$20 -> #REF! | G8: =#REF!+'L-7 KEY NEW(JPVE)'!$T$20 -> #REF! | H8: =#REF!+'L-7 KEY NEW(JPVE)'!$T$20 -> #REF! | I8: =#REF!+'L-7 KEY NEW(JPVE)'!$T$20 -> #REF! | J8: =#REF!+'L-7 KEY NEW(JPVE)'!$T$20 -> #REF! | ... AG8: =#REF!+'L-7 KEY NEW(JPVE)'!$T$20 -> #REF!
A9: ZERO MILE | B9: =B8+'L-7 KEY NEW(JPVE)'!$M5 -> 0.25461806 | C9: =C8+'L-7 KEY NEW(JPVE)'!$M5 -> #REF! | D9: =D8+'L-7 KEY NEW(JPVE)'!$M5 -> #REF! | E9: =E8+'L-7 KEY NEW(JPVE)'!$M5 -> #REF! | F9: =F8+'L-7 KEY NEW(JPVE)'!$M5 -> #REF! | G9: =G8+'L-7 KEY NEW(JPVE)'!$M5 -> #REF! | H9: =H8+'L-7 KEY NEW(JPVE)'!$M5 -> #REF! | I9: =I8+'L-7 KEY NEW(JPVE)'!$M5 -> #REF! | ... AF9: =AF8+'L-7 KEY NEW(JPVE)'!$M5 -> #REF!
A10: NEW ISBT | B10: =B9+'L-7 KEY NEW(JPVE)'!$M6 -> 0.25765046 | C10: =C9+'L-7 KEY NEW(JPVE)'!$M6 -> #REF! | D10: =D9+'L-7 KEY NEW(JPVE)'!$M6 -> #REF! | E10: =E9+'L-7 KEY NEW(JPVE)'!$M6 -> #REF! | F10: =F9+'L-7 KEY NEW(JPVE)'!$M6 -> #REF! | G10: =G9+'L-7 KEY NEW(JPVE)'!$M6 -> #REF! | H10: =H9+'L-7 KEY NEW(JPVE)'!$M6 -> #REF! | I10: =I9+'L-7 KEY NEW(JPVE)'!$M6 -> #REF! | ... AF10: =AF9+'L-7 KEY NEW(JPVE)'!$M6 -> #REF!
A11: REVERSAL FROM | B11: JPVE DN | C11: JPVE DN | D11: JPVE DN | E11: JPVE DN | F11: JPVE DN | G11: JPVE DN | H11: JPVE DN | I11: JPVE DN | J11: JPVE DN | K11: JPVE DN | L11: JPVE DN | M11: JPVE DN | N11: JPVE DN | O11: JPVE DN | P11: JPVE DN | Q11: JPVE DN | R11: JPVE DN | S11: JPVE DN | T11: JPVE DN | U11: JPVE DN | V11: JPVE DN | W11: JPVE DN | X11: JPVE DN | Y11: JPVE DN | Z11: JPVE DN | AA11: JPVE DN | AB11: JPVE DN | AC11: JPVE DN | AD11: JPVE DN | AE11: JPVE DN | AF11: JPVE DN | AG11: JPVE DN STABLE

Sheet L-7 KEY NEW(JPVE)
A1: LINE-7 NEW RUN TIME GIVEN BY AT | DV1: =#REF! -> #REF! | DW1: =#REF! -> #REF!
A2: SECTION | B2: DN LINE AS PER AT | J2: UP LINE AS PER AT
B3: WHEEL START- WHEEL STOP TIME (G) | C3: DWELL TIME (H) | D3: MKPR-SVVR | E3: MKPR-MUPR | F3: MUPR-SVVR | G3: PILOTING (OLD) | H3: PILOTING WHEEL START-WHEEL STOP TIME BY CC 11.08.2024 | I3: PILOTING WITH DWELL TIME | J3: WHEEL START- WHEEL STOP TIME (WITH RESPONSE TIME) (A) | K3: WHEEL START- WHEEL STOP TIME (G) | L3: DWELL TIME (H) | M3: SVVR-MKPR | N3: MUPR-MKPR | O3: SVVR-MUPR | P3: PILOTING (OLD) | Q3: PILOTING WHEEL START-WHEEL STOP TIME BY CC 11.08.2024 | R3: PILOTING WITH DWELL TIME
A5: JPVE-JRMR | B5: 0.0018981481 | C5: 0.00046296296 | D5: =B5+C5 -> 0.0023611111 | H5: 0.0025 | I5: =H5+C5 -> 0.002962963 | J5: MKPR-BURI | K5: 0.0041550926 | L5: 0.00046296296 | M5: =K5+L5 -> 0.0046180556 | Q5: 0.005462963 | R5: =Q5+L5 -> 0.0059259259
A6: JRMR-BURI | B6: 0.0025694444 | C6: 0.00046296296 | D6: =B6+C6 -> 0.0030324074 | H6: 0.0033796296 | I6: =H6+C6 -> 0.0038425926 | J6: BURI-JRMR | K6: 0.0025694444 | L6: 0.00046296296 | M6: =K6+L6 -> 0.0030324074 | Q6: 0.0033796296 | R6: =Q6+L6 -> 0.0038425926 | T6: =M5+M6+M7 -> 0.0095486111 | U6: 0.0010416667 | V6: =U6+T6 -> 0.010590278
A7: BURI-MKPR | B7: 0.0053703704 | D7: =B7+C7 -> 0.0053703704 | H7: 0.0065046296 | I7: =H7+C7 -> 0.0065046296 | J7: JRMR-JPVE | K7: 0.0018981481 | M7: =K7+L7 -> 0.0018981481 | Q7: 0.0025 | R7: =Q7+L7 -> 0.0025 | T7: 0.010763889 | U7: 0.0010416667 | V7: =U7+T7 -> 0.011805556
A9: MKPR - AZU | B9: 0.0020601852 | C9: 0.00039351852 | D9: =B9+C9 -> 0.0024537037 | E9: =B9+C9 -> 0.0024537037 | G9: 0.0028009259 | H9: 0.0026851852 | I9: 0.0030787037 | J9: SVVR - JIEE | K9: 0.0010185185 | L9: 0.00039351852 | M9: =K9+L9 -> 0.001412037 | O9: =K9+L9 -> 0.001412037 | P9: 0.0016550926 | Q9: 0.0012615741 | R9: 0.0016550926
A10: AZU - SMBG | B10: 0.0014814815 | C10: 0.00039351852 | D10: =B10+C10 -> 0.001875 | E10: =B10+C10 -> 0.001875 | G10: 0.002337963 | H10: 0.002037037 | I10: 0.0024305556 | J10: JIEE - GKPR | K10: 0.001412037 | L10: 0.00039351852 | M10: =K10+L10 -> 0.0018055556 | O10: =K10+L10 -> 0.0018055556 | P10: 0.0019097222 | Q10: 0.0015972222 | R10: 0.0019907407 | DJ10: 0.83680556 | DK10: 0.84166667 | DL10: 0.84722222
A11: SMBG - NSHP | B11: 0.0013541667 | C11: 0.00039351852 | D11: =B11+C11 -> 0.0017476852 | E11: =B11+C11 -> 0.0017476852 | G11: 0.0023148148 | H11: 0.0019444444 | I11: 0.002337963 | J11: GKPR - MUPR | K11: 0.0019444444 | L11: 0.00039351852 | M11: =K11+L11 -> 0.002337963 | O11: 0.0019444444 | P11: 0.0020138889 | Q11: 0.0016435185 | R11: 0.002037037
A12: NSHP - SAKP | B12: 0.0012731481 | C12: 0.00039351852 | D12: =B12+C12 -> 0.0016666667 | E12: =B12+C12 -> 0.0016666667 | G12: 0.0019907407 | H12: 0.0014930556 | I12: 0.0018865741 | J12: MUPR - JFRB | K12: 0.0013425926 | L12: 0.00039351852 | M12: =K12+L12 -> 0.0017361111 | N12: =K12+L12 -> 0.0017361111 | P12: 0.0023032407 | Q12: 0.0015046296 | R12: 0.0018981481
A13: SAKP - PBGW | B13: 0.001875 | C13: 0.00045138889 | D13: =B13+C13 -> 0.0023263889 | E13: =B13+C13 -> 0.0023263889 | G13: 0.0028009259 | H13: 0.0025 | I13: 0.0029513889 | J13: JFRB - WC | K13: 0.0019097222 | L13: 0.00045138889 | M13: =K13+L13 -> 0.0023611111 | N13: =K13+L13 -> 0.0023611111 | P13: 0.0027777778 | Q13: 0.0022337963 | R13: 0.0026851852
A14: PVGW - ESIH | B14: 0.0016435185 | C14: 0.00039351852 | D14: =B14+C14 -> 0.002037037 | E14: =B14+C14 -> 0.002037037 | G14: 0.0024652778 | H14: 0.0025 | I14: 0.0028935185 | J14: WC - EANR | K14: 0.0014814815 | L14: 0.00039351852 | M14: =K14+L14 -> 0.001875 | N14: =K14+L14 -> 0.001875 | P14: 0.0023726852 | Q14: 0.0016203704 | R14: 0.0020138889
A15: ESIH - RG | B15: 0.0010185185 | C15: 0.00045138889 | D15: =B15+C15 -> 0.0014699074 | E15: =B15+C15 -> 0.0014699074 | G15: 0.0018981481 | H15: 0.0012384259 | I15: 0.0016898148 | J15: EANR - KHNA | K15: 0.0009837963 | L15: 0.00039351852 | M15: =K15+L15 -> 0.0013773148 | N15: =K15+L15 -> 0.0013773148 | P15: 0.0016203704 | Q15: 0.0012152778 | R15: 0.0016087963
A16: RG - MYPI | B16: 0.0015856481 | C16: 0.00039351852 | D16: =B16+C16 -> 0.0019791667 | E16: =B16+C16 -> 0.0019791667 | G16: 0.0024074074 | H16: 0.0020717593 | I16: 0.0024652778 | J16: KHNA - KKDC | K16: 0.0010763889 | L16: 0.00039351852 | M16: =K16+L16 -> 0.0014699074 | N16: =K16+L16 -> 0.0014699074 | P16: 0.0017824074 | Q16: 0.0011226852 | R16: 0.0015162037
A17: MYPI - NAVR | B17: 0.0016319444 | C17: 0.00039351852 | D17: =B17+C17 -> 0.002025463 | E17: =B17+C17 -> 0.002025463 | G17: 0.0024421296 | H17: 366.00207 | I17: 366.00247 | J17: KKDC - KKDA | K17: 0.0014930556 | L17: 0.00039351852 | M17: =K17+L17 -> 0.0018865741 | N17: =K17+L17 -> 0.0018865741 | P17: 0.0022337963 | Q17: 0.0016782407 | R17: 0.0020717593
A18: NAVR - DLIC | B18: 0.001712963 | C18: 0.00039351852 | D18: =B18+C18 -> 0.0021064815 | E18: =B18+C18 -> 0.0021064815 | G18: 0.0025462963 | H18: 0.0022800926 | I18: 0.0026736111 | J18: KKDA - AVIT | K18: 0.0013657407 | L18: 0.00039351852 | M18: =K18+L18 -> 0.0017592593 | N18: =K18+L18 -> 0.0017592593 | P18: 0.0020833333 | Q18: 0.0015625 | R18: 0.0019560185
A19: DLIC - DDSC | B19: 0.0026967593 | C19: 0.00039351852 | D19: =B19+C19 -> 0.0030902778 | E19: =B19+C19 -> 0.0030902778 | G19: 0.0037152778 | H19: 0.0044212963 | I19: 0.0048148148 | J19: AVIT - IPE | K19: 0.0026388889 | L19: 0.00039351852 | M19: =K19+L19 -> 0.0030324074 | N19: =K19+L19 -> 0.0030324074 | P19: 0.0036226852 | Q19: 0.0028240741 | R19: 0.0032175926
A20: DDSC - SVMB | B20: 0.0013310185 | C20: 0.00039351852 | D20: =B20+C20 -> 0.001724537 | E20: =B20+C20 -> 0.001724537 | G20: 0.0020486111 | H20: 0.0016898148 | I20: 0.0020833333 | J20: IPE - VNNR | K20: 0.0015393519 | L20: 0.00039351852 | M20: =K20+L20 -> 0.0019328704 | N20: =K20+L20 -> 0.0019328704 | P20: 0.0022916667 | Q20: 0.0016782407 | R20: 0.0020717593 | T20: 0.0010416667 | U20: 0.011111111
A21: SVMB - BKCP | B21: 0.0014814815 | C21: 0.00045138889 | D21: =B21+C21 -> 0.0019328704 | E21: =B21+C21 -> 0.0019328704 | G21: 0.0022453704 | H21: 0.0019907407 | I21: 0.0024421296 | J21: VNNR - VENT | K21: 0.0011921296 | L21: 0.00039351852 | M21: =K21+L21 -> 0.0015856481 | N21: =K21+L21 -> 0.0015856481 | P21: 0.0014351852 | Q21: 0.0012037037 | R21: 0.0015972222 | T21: 0.012326389
A22: BKCP - SOJI | B22: 0.00125 | C22: 0.00045138889 | D22: =B22+C22 -> 0.0017013889 | E22: =B22+C22 -> 0.0017013889 | G22: 0.0019791667 | H22: 0.001724537 | I22: 0.0021759259 | J22: VENT - TKPR | K22: 0.0012847222 | L22: 0.00039351852 | M22: =K22+L22 -> 0.0016782407 | N22: =K22+L22 -> 0.0016782407 | P22: 0.0020138889 | Q22: 0.0013194444 | R22: 0.001712963 | T22: 0.024652778
A23: SOJI - INA | B23: 0.0011458333 | C23: 0.00045138889 | D23: =B23+C23 -> 0.0015972222 | E23: =B23+C23 -> 0.0015972222 | G23: 0.0019097222 | H23: 0.0013541667 | I23: 0.0018055556 | J23: TKPR-MVPO | K23: 0.0016435185 | L23: 0.00039351852 | M23: =K23+L23 -> 0.002037037 | N23: =K23+L23 -> 0.002037037 | P23: 0.0023958333 | Q23: 0.0018865741 | R23: 0.0022800926
A24: INA - SOEN | B24: 0.0013310185 | C24: 0.00045138889 | D24: =B24+C24 -> 0.0017824074 | E24: =B24+C24 -> 0.0017824074 | G24: 0.0020486111 | H24: 0.0016898148 | I24: 0.0021412037 | J24: MVPO- MVPI | K24: 0.0010185185 | L24: 0.00039351852 | M24: =K24+L24 -> 0.001412037 | N24: =K24+L24 -> 0.001412037 | P24: 0.0016782407 | Q24: 0.0011226852 | R24: 0.0015162037
A25: SOEN - LJPN | B25: 0.0015856481 | C25: 0.00039351852 | D25: =B25+C25 -> 0.0019791667 | E25: =B25+C25 -> 0.0019791667 | G25: 0.0024305556 | H25: 0.0022453704 | I25: 0.0026388889 | J25: MVPI-NZM | K25: 0.0033796296 | L25: 0.00045138889 | M25: =K25+L25 -> 0.0038310185 | N25: =K25+L25 -> 0.0038310185 | P25: 0.0039930556 | Q25: 0.0049189815 | R25: 0.0053703704
A26: LJPN-VNPR | B26: 0.00125 | C26: 0.00039351852 | D26: =B26+C26 -> 0.0016435185 | E26: =B26+C26 -> 0.0016435185 | G26: 0.0019675926 | H26: 0.0016087963 | I26: 0.0020023148 | J26: NZM- AHRM | K26: 0.0017476852 | L26: 0.00039351852 | M26: =K26+L26 -> 0.0021412037 | N26: =K26+L26 -> 0.0021412037 | P26: 0.0025578704 | Q26: 0.0024421296 | R26: 0.0028356481
A27: VNPR-AHRM | B27: 0.0013078704 | C27: 0.00039351852 | D27: =B27+C27 -> 0.0017013889 | E27: =B27+C27 -> 0.0017013889 | G27: 0.0019907407 | H27: 0.0015625 | I27: 0.0019560185 | J27: ASHM-VNPR | K27: 0.0013541667 | L27: 0.00039351852 | M27: =K27+L27 -> 0.0017476852 | N27: =K27+L27 -> 0.0017476852 | P27: 0.0020138889 | Q27: 0.0015277778 | R27: 0.0019212963
A28: ASHM-NZM | B28: 0.0017361111 | C28: 0.00045138889 | D28: =B28+C28 -> 0.0021875 | E28: =B28+C28 -> 0.0021875 | G28: 0.0025115741 | H28: 0.0025231481 | I28: 0.002974537 | J28: VNPR - LJPN | K28: 0.0012847222 | L28: 0.00039351852 | M28: =K28+L28 -> 0.0016782407 | N28: =K28+L28 -> 0.0016782407 | P28: 0.0020023148 | Q28: 0.0016203704 | R28: 0.0020138889
A29: NZM-MVPI | B29: 0.0029861111 | C29: 0.00039351852 | D29: =B29+C29 -> 0.0033796296 | E29: =B29+C29 -> 0.0033796296 | G29: 0.0039930556 | H29: 0.0048958333 | I29: 0.0052893519 | J29: LJPN - SOEN | K29: 0.0014814815 | L29: 0.00045138889 | M29: =K29+L29 -> 0.0019328704 | N29: =K29+L29 -> 0.0019328704 | P29: 0.0024305556 | Q29: 0.0021990741 | R29: 0.002650463
A30: MVPI-MVPO | B30: 0.0010300926 | C30: 0.00039351852 | D30: =B30+C30 -> 0.0014236111 | E30: =B30+C30 -> 0.0014236111 | G30: 0.0016666667 | H30: 0.0011689815 | I30: 0.0015625 | J30: SOEN - INA | K30: 0.0013310185 | L30: 0.00045138889 | M30: =K30+L30 -> 0.0017824074 | N30: =K30+L30 -> 0.0017824074 | P30: 0.0020833333 | Q30: 0.0017013889 | R30: 0.0021527778
A31: MVPO-TKPR | B31: 0.0017592593 | C31: 0.00039351852 | D31: =B31+C31 -> 0.0021527778 | E31: =B31+C31 -> 0.0021527778 | G31: 0.0024189815 | H31: 0.0019212963 | I31: 0.0023148148 | J31: INA - SOJI | K31: 0.0011111111 | L31: 0.00045138889 | M31: =K31+L31 -> 0.0015625 | N31: =K31+L31 -> 0.0015625 | P31: 0.0020601852 | Q31: 0.0013541667 | R31: 0.0018055556
A32: TKPR - VENT | B32: 0.0012731481 | C32: 0.00039351852 | D32: =B32+C32 -> 0.0016666667 | E32: =B32+C32 -> 0.0016666667 | G32: 0.002025463 | H32: 0.0013888889 | I32: 0.0017824074 | J32: SOJI - BKCP | K32: 0.0012731481 | L32: 0.00045138889 | M32: =K32+L32 -> 0.001724537 | N32: =K32+L32 -> 0.001724537 | P32: 0.0019791667 | Q32: 0.0016666667 | R32: 0.0021180556
A33: VENT - VNNR | B33: 0.0011921296 | C33: 0.00039351852 | D33: =B33+C33 -> 0.0015856481 | E33: =B33+C33 -> 0.0015856481 | G33: 0.0018634259 | H33: 0.0012384259 | I33: 0.0016319444 | J33: BKCP - SVMB | K33: 0.0014583333 | L33: 0.00039351852 | M33: =K33+L33 -> 0.0018518519 | N33: =K33+L33 -> 0.0018518519 | P33: 0.0022337963 | Q33: 0.0020138889 | R33: 0.0024074074
A34: VNNR - IPE | B34: 0.0015740741 | C34: 0.00039351852 | D34: =B34+C34 -> 0.0019675926 | E34: =B34+C34 -> 0.0019675926 | G34: 0.002337963 | H34: 0.0016666667 | I34: 0.0020601852 | J34: SVMB - DDSC | K34: 0.0012847222 | L34: 0.00039351852 | M34: =K34+L34 -> 0.0016782407 | N34: =K34+L34 -> 0.0016782407 | P34: 0.0019560185 | Q34: 0.0017592593 | R34: 0.0021527778
... A41: WC - JFRB | B41: 0.0018981481 | C41: 0.00039351852 | D41: =B41+C41 -> 0.0022916667 | E41: =B41+C41 -> 0.0022916667 | G41: 0.0027546296 | H41: 0.0022222222 | I41: 0.0026157407 | J41: PVGW - SAKP | K41: 0.0016550926 | L41: 0.00039351852 | M41: =K41+L41 -> 0.0020486111 | N41: =K41+L41 -> 0.0020486111 | P41: 0.0024652778 | Q41: 0.0022800926 | R41: 0.0026736111
A42: JFRB - MUPR | B42: 0.0016435185 | C42: 0.00039351852 | D42: =B42+C42 -> 0.002037037 | E42: 0.0016435185 | G42: 0.0023032407 | H42: 0.0015393519 | I42: 0.0019328704 | J42: SAKP - NSHP | K42: 0.0015509259 | L42: 0.00039351852 | M42: =K42+L42 -> 0.0019444444 | N42: =K42+L42 -> 0.0019444444 | P42: 0.0017476852 | Q42: 0.0016898148 | R42: 0.0020833333
A43: MUPR - GKPR | B43: 0.00125 | C43: 0.00039351852 | D43: =B43+C43 -> 0.0016435185 | F43: =B43+C43 -> 0.0016435185 | G43: 0.001724537 | H43: 0.0016782407 | I43: 0.0020717593 | J43: NSHP - SMBG | K43: 0.0013773148 | L43: 0.00039351852 | M43: =K43+L43 -> 0.0017708333 | N43: =K43+L43 -> 0.0017708333 | P43: 0.0028819444 | Q43: 0.0018865741 | R43: 0.0022800926
A44: GKPR - JIEE | B44: 0.001412037 | C44: 0.00039351852 | D44: =B44+C44 -> 0.0018055556 | F44: =B44+C44 -> 0.0018055556 | G44: 0.0019097222 | H44: 0.0016666667 | I44: 0.0020601852 | J44: SMBG - AZU | K44: 0.0018518519 | L44: 0.00039351852 | M44: =K44+L44 -> 0.0022453704 | N44: =K44+L44 -> 0.0022453704 | P44: 0.0028472222 | Q44: 0.0020023148 | R44: 0.0023958333
A45: JIEE - SVVR | B45: 0.0011805556 | D45: =B45+C45 -> 0.0011805556 | F45: =B45+C45 -> 0.0011805556 | G45: 0.0016550926 | H45: 0.0014236111 | I45: 0.0014236111 | J45: AZU - MKPR | K45: 0.002337963 | M45: =K45+L45 -> 0.002337963 | N45: =K45+L45 -> 0.002337963 | P45: 0.0026041667 | Q45: 0.0028587963 | R45: 0.0028587963
B46: =SUM(B9:B45) -> 0.056805556 | C46: =SUM(C9:C45) -> 0.01462963 | D46: =SUM(D9:D45) -> 0.071435185 | E46: =SUM(E9:E45) -> 0.066412037 | F46: =SUM(F43:F45) -> 0.0046296296 | G46: =SUM(G9:G45) -> 0.085138889 | I46: 366.08701 | K46: =SUM(K9:K45) -> 0.058078704 | L46: =SUM(L9:L45) -> 0.01462963 | M46: =SUM(M9:M45) -> 0.072708333 | N46: =SUM(N9:N45) -> 0.067152778 | O46: =SUM(O9:O45) -> 0.005162037 | P46: =SUM(P9:P45) -> 0.08505787 | R46: =SUM(R9:R45) -> 0.086238426
A47: 0.013888889 | E47: =E46+$A$47 -> 0.080300926 | M47: =M46+$A$47 -> 0.086597222 | N47: =N46+$A$47 -> 0.081041667
K49: 0.015497685 | L49: =K49+$A$47 -> 0.029386574 | DI49: 0.90625
...

Sheet MKPR-JPVE UP MON-SUN
A1: MKPR-JPVE SECTION MONDAY- SUNDAY TIME TABLE
A2: TRAIN NO. | C2: 798 | D2: 798 | E2: 798 | F2: 798 | G2: 798 | H2: 798 | I2: 798 | J2: 798 | K2: 798 | L2: 798 | M2: 798 | N2: 798
B3: UP LINE | C3: UP LINE | D3: UP LINE | E3: UP LINE | F3: UP LINE | G3: UP LINE | H3: UP LINE | I3: UP LINE | J3: UP LINE | K3: UP LINE | L3: UP LINE | M3: UP LINE | N3: UP LINE
A4: JPVE | C4: NON REVENUE PILOTING FROM MKPR UP TO JPVE UP @25KMPH | D4: 0.33333333 | E4: =D4+'L-7 KEY NEW(JPVE)'!$T$22 -> 0.35798611 | F4: =E4+'L-7 KEY NEW(JPVE)'!$T$22 -> 0.38263889 | G4: =F4+'L-7 KEY NEW(JPVE)'!$T$22 -> 0.40729167 | H4: =G4+'L-7 KEY NEW(JPVE)'!$T$22 -> 0.43194444 | I4: =H4+'L-7 KEY NEW(JPVE)'!$T$22 -> 0.45659722 | J4: =I4+'L-7 KEY NEW(JPVE)'!$T$22 -> 0.48125 | K4: =J4+'L-7 KEY NEW(JPVE)'!$T$22 -> 0.50590278 | L4: =K4+'L-7 KEY NEW(JPVE)'!$T$22 -> 0.53055556 | ... N4: =M4+'L-7 KEY NEW(JPVE)'!$T$22 -> 0.57986111
